Workbook

Sheet Summary
B2: Name of scheme | C2: Ong | F2: Comments
B3: CCA (ha) | C3: 17276
B4: Total Command Area (ha) | C4: 30837.7
B5: Arable Land (ha) | C5: 16663
B6: Irrigable Land (ha) | C6: 13657
B7: Number of Years | C7: =COUNT(_xlfn.UNIQUE('Data(perCrop)'!O:O)) -> 5 | F7: Consider years within the period 2018-2022 only
B9: Sheets | C9: Description | D9: Inputs Required | E9: Optional Inputs | F9: Comments
B10: SCORES | C10: Benchmarking: final values and scores | D10: Yes | E10: Yes
B11: Data(perSeason,perCrop) | C11: Data exported from GEE (per season, per crop, per year) | D11: Yes
B12: Data(perCrop) | C12: Data exported from GEE (per crop and per year) | D12: Yes
B13: Data(FAO-AQUASTAT) | C13: Crop water requirements according to FAO-AQUASTAT | D13: Yes | F13: Fraction of irrigated area currently represented: | G13: =Indicators!F42 -> 0.71602852
B14: Indicators | C14: Annual benchmarking indicators, overall
B15: Indicators(perCrop) | C15: Annual benchmarking indicators, per crop type
B16: SummaryTable | C16: Summary table of benchmarking statistics
B17: Figures | C17: Figures
B19: Indicator | C19: Description | D19: Unit | E19: Temporal Resolution | F19: Required Inputs | G19: Comment
A20: 1 | B20: Cropping Intensity | D20: - | E20: Annual | F20: "Data(perSeason,perCrop)": Area | G20: Calculate based on CCA
A21: 2 | B21: Irrigation Utilization | C21: Fraction of command area irrigated | D21: % | E21: Seasonal or Annual | F21: "Data(perSeason,perCrop)": Area | G21: Calculate based on CCA
A22: 3 | B22: Low Water Intensive Crops | C22: Fraction of low water intensive irrigated crops | D22: % | E22: Seasonal or Annual | F22: "Data(FAO-AQUASTAT)": ETc-Crop "Data(perCrop)": Area | G22: https://aquastat.fao.org/
A23: 4 | B23: Adequacy | C23: RWD=1-(Eta/Etp) | D23: - | E23: Seasonal or Annual | F23: "Data(perCrop)": Area, ETa, ETaMax
A24: 5 | B24: Equity | C24: Standard deviation of ETa over irrigated areas divided by average ETa | D24: - | E24: Seasonal or Annual | F24: "Data(perSeason,perCrop)": ETcv or Etcv_blue
A25: 6 | B25: Productivity | C25: Water Productivity (in terms of yield) | D25: kg/m3 | E25: Annual (per crop) | F25: "Data(perCrop)": TBP, ETa
A26: 7 | B26: Reliability | C26: Range of average crop-specific monthly Relative ET (ET/ETp), considering for each scheme the most common irrigated crop(s) and the corresponding cropping season | D26: % | E26: Annual (per crop) | F26: "Data(perSeason,perCrop)": RETmax, RETmin "Data(perCrop)": Area
A27: 8 | B27: Yield Gap due to water stress | C27: (Ypotential​−Yactual​​)/(Ypotential​)×100 | D27: % | E27: Annual (per crop) | F27: "Data(perCrop)": TBP, TBP_P

Sheet SCORES
B1: Indicator | C1: Description | D1: Units | E1: Crop Specific (Y/N) | F1: Crop Types | G1: Descending/Ascending | H1: Parameter | I1: Parameter value | J1: Critical Value | K1: Target Value | L1: Season (s) | P1: Indicator Weight | Q1: Value | R1: Score
L2: Kharif | M2: Rabi | N2: Zaid | O2: Annual
A3: 1 | B3: Cropping Intensity | C3: Cropping Intensity, considering CCA | D3: %/100 | E3: N | F3: All Annual Crops | G3: A | J3: 1 | K3: 1.5 | O3: 1 | P3: 1 | Q3: =Indicators!F61 -> 0.86742226 | R3: =IF($G3="D",MIN(MAX(1,11-ROUND(((Q3-$K3)/($J3-$K3))*9+1,0)),10),MIN(MAX(1,ROUND(((Q3-$J3)/($K3-$J3))*9+1,0)),10)) -> 1
A4: 2 | B4: Irrigation Utilization | C4: Fraction of CCA irrigated | D4: %/100 | E4: N | F4: All Irrigated Crops | G4: A | J4: 0.25 | K4: 0.8 | O4: 1 | P4: 1 | Q4: =(L4*Indicators!C34+SCORES!M4*Indicators!D34+SCORES!N4*Indicators!E34+SCORES!O4*Indicators!F34)/SUM(L4:O4) -> 0.49118117 | R4: =IF($G4="D",MIN(MAX(1,11-ROUND(((Q4-$K4)/($J4-$K4))*9+1,0)),10),MIN(MAX(1,ROUND(((Q4-$J4)/($K4-$J4))*9+1,0)),10)) -> 5
A5: 3 | B5: Low Water Intensive Crops | C5: Fraction of low water intensive irrigated crops, based on FAO-AQUASTAT crop water requirements | D5: %/100 | E5: Y | F5: All irrigated Crops, based on FAO-AQUASTAT crop water requirements | G5: A | H5: Threshold value to identify water intensive crops, per full cropping period [mm] | I5: 500 | J5: 0.25 | K5: 0.8 | O5: 1 | P5: 0 | Q5: =Indicators!F48 -> 0.074714178 | R5: =IF($G5="D",MIN(MAX(1,11-ROUND(((IF(ISNUMBER(Q5),Q5,Q6)-$K5)/($J5-$K5))*9+1,0)),10),MIN(MAX(1,ROUND(((IF(ISNUMBER(Q5),Q5,Q6)-$J5)/($K5-$J5))*9+1,0)),10)) -> 1
E6: N | F6: All irrigated Crops, based on Etp (90th percentile of ETa according to RS analysis) | G6: A | H6: Threshold value to identify water intensive crops, per season [mm] | I6: 300 | J6: 0 | K6: 1 | L6: 1 | M6: 1 | O6: 1 | Q6: =(L6*Indicators!C40+SCORES!M6*Indicators!D36+SCORES!N6*Indicators!E40+SCORES!O6*Indicators!F40)/SUM(L6:O6) -> 0.36621048
A7: 4 | B7: Adequacy | C7: RWD=1-(Eta/Etp) | D7: - | E7: N | F7: Weighted mean of all crops (weighted by irrigated area per crop) | G7: D | J7: 0.25 | K7: 0.8 | O7: 1 | P7: 1 | Q7: =(L7*Indicators!C67+SCORES!M7*Indicators!D67+SCORES!N7*Indicators!E67+SCORES!O7*Indicators!F67)/SUM(L7:O7) -> 0.24726081 | R7: =IF($G7="D",MIN(MAX(1,11-ROUND(((Q7-$K7)/($J7-$K7))*9+1,0)),10),MIN(MAX(1,ROUND(((Q7-$J7)/($K7-$J7))*9+1,0)),10)) -> 1
A8: 5 | B8: Equity | C8: Standard deviation of ETa over irrigated areas divided by average ETa | D8: - | E8: N | F8: Weighted mean of all crops (weighted by irrigated area per crop) | G8: D | J8: 0.4 | K8: 0 | O8: 1 | P8: 1 | Q8: =(L8*Indicators!C73+SCORES!M8*Indicators!D73+SCORES!N8*Indicators!E73+SCORES!O8*Indicators!F73)/SUM(L8:O8) -> 0.10352414 | R8: =IF($G8="D",MIN(MAX(1,11-ROUND(((Q8-$K8)/($J8-$K8))*9+1,0)),10),MIN(MAX(1,ROUND(((Q8-$J8)/($K8-$J8))*9+1,0)),10)) -> 8
C9: Standard deviation of ETblue over irrigated areas divided by average ETblue | D9: - | E9: N | F9: Weighted mean of all crops (weighted by irrigated area per crop) | G9: D | K9: 0 | M9: 1 | P9: 0 | Q9: =(L9*Indicators!C79+SCORES!M9*Indicators!D79+SCORES!N9*Indicators!E79+SCORES!O9*Indicators!F79)/SUM(L9:O9) -> 0.4539919 | R9: =IF(ISNUMBER(J9),IF($G9="D",MIN(MAX(1,11-ROUND(((Q9-$K9)/($J9-$K9))*9+1,0)),10),MIN(MAX(1,ROUND(((Q9-$J9)/($K9-$J9))*9+1,0)),10)),"")
A10: 6 | B10: Productivity | C10: Water Productivity (in terms of yield) | D10: kg/m3 | E10: Y | P10: 1 | R10: =AVERAGE(R11:R16) -> 10
F11: Cotton | G11: A | J11: 0.10559418 | K11: 0.41678402 | Q11: ='Indicators(perCrop)'!BA5 -> #DIV/0! | R11: =IF(ISNUMBER(Q11),IF($G11="D",MIN(MAX(1,11-ROUND(((Q11-$K11)/($J11-$K11))*9+1,0)),10),MIN(MAX(1,ROUND(((Q11-$J11)/($K11-$J11))*9+1,0)),10)),"")
F12: Jowar | G12: A | J12: 0.53490679 | K12: 0.8184797 | Q12: ='Indicators(perCrop)'!BA12 -> #DIV/0! | R12: =IF(ISNUMBER(Q12),IF($G12="D",MIN(MAX(1,11-ROUND(((Q12-$K12)/($J12-$K12))*9+1,0)),10),MIN(MAX(1,ROUND(((Q12-$J12)/($K12-$J12))*9+1,0)),10)),"")
F13: Paddy | G13: A | J13: 0.46496334 | K13: 1 | Q13: ='Indicators(perCrop)'!BA6 -> 1.104788 | R13: =IF(ISNUMBER(Q13),IF($G13="D",MIN(MAX(1,11-ROUND(((Q13-$K13)/($J13-$K13))*9+1,0)),10),MIN(MAX(1,ROUND(((Q13-$J13)/($K13-$J13))*9+1,0)),10)),"") -> 10
F14: Sugarcane | G14: A | J14: 3.8966165 | K14: 5.234192 | Q14: ='Indicators(perCrop)'!BA17 -> #DIV/0! | R14: =IF(ISNUMBER(Q14),IF($G14="D",MIN(MAX(1,11-ROUND(((Q14-$K14)/($J14-$K14))*9+1,0)),10),MIN(MAX(1,ROUND(((Q14-$J14)/($K14-$J14))*9+1,0)),10)),"")
F15: Mustard (Forage) | G15: A | J15: 2.9234075 | K15: 3.6598924 | Q15: ='Indicators(perCrop)'!BA11 -> #DIV/0! | R15: =IF(ISNUMBER(Q15),IF($G15="D",MIN(MAX(1,11-ROUND(((Q15-$K15)/($J15-$K15))*9+1,0)),10),MIN(MAX(1,ROUND(((Q15-$J15)/($K15-$J15))*9+1,0)),10)),"")
F16: Wheat | G16: A | J16: 1.0734831 | K16: 1.4866771 | Q16: ='Indicators(perCrop)'!BA8 -> #DIV/0! | R16: =IF(ISNUMBER(Q16),IF($G16="D",MIN(MAX(1,11-ROUND(((Q16-$K16)/($J16-$K16))*9+1,0)),10),MIN(MAX(1,ROUND(((Q16-$J16)/($K16-$J16))*9+1,0)),10)),"")
A17: 7 | B17: Reliability | C17: Range of average crop-specific monthly Relative ET (ET/ETp) | D17: %/100 | E17: N | F17: Weighted mean of all crops (weighted by irrigated area per crop) | G17: D | J17: 0.4 | K17: 0 | P17: 1 | Q17: =Indicators!F92 -> 0.26708584 | R17: =IF($G17="D",MIN(MAX(1,11-ROUND(((Q17-$K17)/($J17-$K17))*9+1,0)),10),MIN(MAX(1,ROUND(((Q17-$J17)/($K17-$J17))*9+1,0)),10)) -> 4
A18: 8 | B18: Yield Gap due to water stress | C18: (Ypotential​−Yactual​​)/(Ypotential​)×100 | D18: %/100 | E18: N | F18: Weighted mean of all crops (weighted by irrigated area per crop) | G18: D | J18: 0.4 | K18: 0 | P18: 1 | Q18: =Indicators!F99 -> 0.23714847 | R18: =IF($G18="D",MIN(MAX(1,11-ROUND(((Q18-$K18)/($J18-$K18))*9+1,0)),10),MIN(MAX(1,ROUND(((Q18-$J18)/($K18-$J18))*9+1,0)),10)) -> 5
Q20: AVERAGE SCORE | R20: =(SUMPRODUCT($P7:$P10,R7:R10)+SUMPRODUCT($P17:$P18,R17:R18)+SUMPRODUCT($P3:$P5,R3:R5))/SUM($P7:$P10,$P17:$P18,P3:P5) -> 4.8571429

Sheet SummaryTable
A1: =SCORES!B1 -> Indicator | B1: =SCORES!C1 -> Description | C1: =SCORES!D1 -> Units | D1: =SCORES!J1 -> Critical Value | E1: =SCORES!K1 -> Target Value | F1: =SCORES!Q1 -> Value | G1: Score
A2: =SCORES!B3 -> Cropping Intensity | B2: =SCORES!C3 -> Cropping Intensity, considering CCA | C2: =SCORES!D3 -> %/100 | D2: =SCORES!J3 -> 1 | E2: =SCORES!K3 -> 1.5 | F2: =SCORES!Q3 -> 0.86742226 | G2: =SCORES!R3 -> 1
A3: =SCORES!B4 -> Irrigation Utilization | B3: =SCORES!C4 -> Fraction of CCA irrigated | C3: =SCORES!D4 -> %/100 | D3: =SCORES!J4 -> 0.25 | E3: =SCORES!K4 -> 0.8 | F3: =SCORES!Q4 -> 0.49118117 | G3: =SCORES!R4 -> 5
A4: =SCORES!B5 -> Low Water Intensive Crops | B4: Fraction of low water intensive irrigated crops | C4: =SCORES!D5 -> %/100 | D4: =SCORES!J5 -> 0.25 | E4: =SCORES!K5 -> 0.8 | F4: =IF(ISNUMBER(SCORES!Q5),SCORES!Q5,SCORES!Q6) -> 0.074714178 | G4: =SCORES!R5 -> 1
A5: =SCORES!B7 -> Adequacy | B5: =SCORES!C7 -> RWD=1-(Eta/Etp) | C5: =SCORES!D7 -> - | D5: =SCORES!J7 -> 0.25 | E5: =SCORES!K7 -> 0.8 | F5: =SCORES!Q7 -> 0.24726081 | G5: =SCORES!R7 -> 1
A6: =SCORES!B8 -> Equity | B6: =SCORES!C8 -> Standard deviation of ETa over irrigated areas divided by average ETa | C6: =SCORES!D8 -> - | D6: =SCORES!J8 -> 0.4 | E6: =SCORES!K8 -> 0 | F6: =SCORES!Q8 -> 0.10352414 | G6: =SCORES!R8 -> 8
A7: =SCORES!B10 -> Productivity | B7: =SCORES!C10 -> Water Productivity (in terms of yield) | C7: =SCORES!D10 -> kg/m3 | G7: =SCORES!R10 -> 10
B8: Cotton | D8: 0.10559418 | E8: 0.41678402 | F8: =SCORES!Q11 -> #DIV/0! | G8: =SCORES!R11
B9: Jowar | D9: 0.53490679 | E9: 0.8184797 | F9: =SCORES!Q12 -> #DIV/0! | G9: =SCORES!R12
B10: Paddy | D10: 0.46496334 | E10: 1 | F10: =SCORES!Q13 -> 1.104788 | G10: =SCORES!R13 -> 10
B11: Sugarcane | D11: 3.8966165 | E11: 5.234192 | F11: =SCORES!Q14 -> #DIV/0! | G11: =SCORES!R14
B12: Mustard (Forage) | D12: 2.9234075 | E12: 3.6598924 | F12: =SCORES!Q15 -> #DIV/0! | G12: =SCORES!R15
B13: Wheat | D13: 1.0734831 | E13: 1.4866771 | F13: =SCORES!Q16 -> #DIV/0! | G13: =SCORES!R16
A14: =SCORES!B17 -> Reliability | B14: =SCORES!C17 -> Range of average crop-specific monthly Relative ET (ET/ETp) | C14: =SCORES!D17 -> %/100 | D14: =SCORES!J17 -> 0.4 | E14: =SCORES!K17 -> 0 | F14: =SCORES!Q17 -> 0.26708584 | G14: =SCORES!R17 -> 4
A15: =SCORES!B18 -> Yield Gap due to water stress | B15: =SCORES!C18 -> (Ypotential​−Yactual​​)/(Ypotential​)×100 | C15: =SCORES!D18 -> %/100 | D15: =SCORES!J18 -> 0.4 | E15: =SCORES!K18 -> 0 | F15: =SCORES!Q18 -> 0.23714847 | G15: =SCORES!R18 -> 5
F16: =SCORES!Q20 -> AVERAGE SCORE | G16: =AVERAGE(G14:G15,G2:G7) -> 4.375

Sheet Data(perSeason,perCrop)
A1: Area | B1: Area% | C1: Crop Type | D1: CropID | E1: ETa | F1: ETa90 | G1: ETblue | H1: ETcv | I1: ETcv_blue | J1: ETgreen | K1: Name | L1: Precip | M1: RETmax | N1: RETmin | O1: Season | P1: TBP | Q1: TBP_P | R1: status | S1: year | T1: Water Intensive (based on Etp)
A2: 892.75171 | B2: 7.6 | C2: Class1 | D2: 31 | E2: 287 | F2: 344 | G2: 68 | H2: 0.12617248 | I2: 0.52725009 | J2: 217 | K2: Ong | L2: 1313 | M2: 0.90091946 | N2: 0.42328921 | O2: 1 | P2: 6243 | Q2: 7324 | R2: IRRIGATED | S2: 2018 | T2: =IF(R2="IRRIGATED",IF(F2>=SCORES!I$6,1,0),"") -> 1
A3: 493.76833 | B3: 4.7 | C3: Class1 | D3: 31 | E3: 222 | F3: 262 | G3: 23 | H3: 0.040802421 | I3: 0.38562956 | J3: 194 | K3: Ong | L3: 52 | M3: 0.91055893 | N3: 0.90898866 | O3: 2 | P3: 5782 | Q3: 8449 | R3: IRRIGATED | S3: 2018 | T3: =IF(R3="IRRIGATED",IF(F3>=SCORES!I$6,1,0),"") -> 0
A4: 486.04367 | B4: 3.8 | C4: Class1 | D4: 31 | E4: 223 | F4: 320 | G4: 22 | H4: 0.042562362 | I4: 0.54302631 | J4: 195 | K4: Ong | L4: 93 | M4: 0.9251526 | N4: 0.90250255 | O4: 2 | P4: 6349 | Q4: 9465 | R4: IRRIGATED | S4: 2019 | T4: =IF(R4="IRRIGATED",IF(F4>=SCORES!I$6,1,0),"") -> 1
A5: 804.6482 | B5: 6 | C5: Class1 | D5: 31 | E5: 235 | F5: 296 | G5: 45 | H5: 0.19330612 | I5: 0.89136115 | J5: 187 | K5: Ong | L5: 1172 | M5: 0.91927536 | N5: 0.35232797 | O5: 1 | P5: 4175 | Q5: 5169 | R5: IRRIGATED | S5: 2019 | T5: =IF(R5="IRRIGATED",IF(F5>=SCORES!I$6,1,0),"") -> 0
A6: 440.46394 | B6: 4.6 | C6: Class1 | D6: 31 | E6: 246 | F6: 286 | G6: 24 | H6: 0.042734244 | I6: 0.44241038 | J6: 216 | K6: Ong | L6: 93 | M6: 0.90312693 | N6: 0.90276147 | O6: 2 | P6: 5737 | Q6: 7741 | R6: IRRIGATED | S6: 2020 | T6: =IF(R6="IRRIGATED",IF(F6>=SCORES!I$6,1,0),"") -> 0
A7: 573.60987 | B7: 5.5 | C7: Class1 | D7: 31 | E7: 321 | F7: 384 | G7: 91 | H7: 0.14251096 | I7: 0.48541482 | J7: 233 | K7: Ong | L7: 1426 | M7: 0.89788855 | N7: 0.54220803 | O7: 1 | P7: 4863 | Q7: 6207 | R7: IRRIGATED | S7: 2020 | T7: =IF(R7="IRRIGATED",IF(F7>=SCORES!I$6,1,0),"") -> 1
A8: 641.35862 | B8: 7.2 | C8: Class1 | D8: 31 | E8: 220 | F8: 288 | G8: 57 | H8: 0.21250162 | I8: 0.65831415 | J8: 165 | K8: Ong | L8: 936 | M8: 0.90406316 | N8: 0.3594775 | O8: 1 | P8: 3775 | Q8: 4904 | R8: IRRIGATED | S8: 2021 | T8: =IF(R8="IRRIGATED",IF(F8>=SCORES!I$6,1,0),"") -> 0
A9: 690.02424 | B9: 8 | C9: Class1 | D9: 31 | E9: 236 | F9: 324 | G9: 26 | H9: 0.043937358 | I9: 0.4247904 | J9: 204 | K9: Ong | L9: 88 | M9: 0.90892786 | N9: 0.90800831 | O9: 2 | P9: 5740 | Q9: 9113 | R9: IRRIGATED | S9: 2021 | T9: =IF(R9="IRRIGATED",IF(F9>=SCORES!I$6,1,0),"") -> 1
A10: 293.05072 | B10: 2.4 | C10: Class1 | D10: 31 | E10: 238 | F10: 296 | G10: 22 | H10: 0.04234814 | I10: 0.47410284 | J10: 211 | K10: Ong | L10: 118 | M10: 0.92030224 | N10: 0.89486402 | O10: 2 | P10: 6625 | Q10: 9433 | R10: IRRIGATED | S10: 2022 | T10: =IF(R10="IRRIGATED",IF(F10>=SCORES!I$6,1,0),"") -> 0
A11: 594.2404 | B11: 4.5 | C11: Class1 | D11: 31 | E11: 265 | F11: 304 | G11: 50 | H11: 0.13123189 | I11: 0.64136107 | J11: 213 | K11: Ong | L11: 1226 | M11: 0.89504882 | N11: 0.49147649 | O11: 1 | P11: 4874 | Q11: 5340 | R11: IRRIGATED | S11: 2022 | T11: =IF(R11="IRRIGATED",IF(F11>=SCORES!I$6,1,0),"") -> 1
A12: 32.092348 | B12: 1.2 | C12: Class1 | D12: 31 | E12: 389 | F12: 493 | G12: 109 | H12: 0.098095935 | I12: 0.33488716 | J12: 278 | K12: Ong | L12: 85 | O12: 3 | P12: 2846 | Q12: 3909 | R12: IRRIGATED | S12: 2018 | T12: =IF(R12="IRRIGATED",IF(F12>=SCORES!I$6,1,0),"") -> 1
A13: 251.30927 | B13: 3.1 | C13: Class1 | D13: 31 | E13: 325 | F13: 438 | G13: 74 | H13: 0.10434804 | I13: 0.4188768 | J13: 248 | K13: Ong | L13: 120 | O13: 3 | P13: 4055 | Q13: 5813 | R13: IRRIGATED | S13: 2019 | T13: =IF(R13="IRRIGATED",IF(F13>=SCORES!I$6,1,0),"") -> 1
A14: 79.21902 | B14: 3.4 | C14: Class1 | D14: 31 | E14: 288 | F14: 417 | G14: 110 | H14: 0.12550526 | I14: 0.33515565 | J14: 177 | K14: Ong | L14: 136 | O14: 3 | P14: 2354 | Q14: 3920 | R14: IRRIGATED | S14: 2020 | T14: =IF(R14="IRRIGATED",IF(F14>=SCORES!I$6,1,0),"") -> 1
A15: 81.540191 | B15: 3.2 | C15: Class1 | D15: 31 | E15: 318 | F15: 449 | G15: 119 | H15: 0.1301173 | I15: 0.31382273 | J15: 198 | K15: Ong | L15: 115 | O15: 3 | P15: 2778 | Q15: 3601 | R15: IRRIGATED | S15: 2021 | T15: =IF(R15="IRRIGATED",IF(F15>=SCORES!I$6,1,0),"") -> 1
A16: 150.65745 | B16: 3.3 | C16: Class1 | D16: 31 | E16: 318 | F16: 417 | G16: 116 | H16: 0.14274506 | I16: 0.39324161 | J16: 201 | K16: Ong | L16: 57 | O16: 3 | P16: 2562 | Q16: 4201 | R16: IRRIGATED | S16: 2022 | T16: =IF(R16="IRRIGATED",IF(F16>=SCORES!I$6,1,0),"") -> 1
A17: 490.68953 | B17: 4.2 | C17: Class1 | D17: 31 | E17: 217 | F17: 246 | G17: 0 | J17: 215 | K17: Ong | L17: 1255 | M17: 0.90091946 | N17: 0.42328921 | O17: 1 | P17: 5039 | R17: RAINFED | S17: 2018 | T17: =IF(R17="IRRIGATED",IF(F17>=SCORES!I$6,1,0),"")
A18: 524.99812 | B18: 5 | C18: Class1 | D18: 31 | E18: 195 | F18: 206 | G18: 0 | J18: 190 | K18: Ong | L18: 51 | M18: 0.91055893 | N18: 0.90898866 | O18: 2 | P18: 4683 | R18: RAINFED | S18: 2018 | T18: =IF(R18="IRRIGATED",IF(F18>=SCORES!I$6,1,0),"")
A19: 1024.7574 | B19: 7.7 | C19: Class1 | D19: 31 | E19: 191 | F19: 228 | G19: 0 | J19: 185 | K19: Ong | L19: 1132 | M19: 0.91927536 | N19: 0.35232797 | O19: 1 | P19: 3474 | R19: RAINFED | S19: 2019 | T19: =IF(R19="IRRIGATED",IF(F19>=SCORES!I$6,1,0),"")
A20: 1159.5292 | B20: 9 | C20: Class1 | D20: 31 | E20: 188 | F20: 276 | G20: 0 | J20: 181 | K20: Ong | L20: 93 | M20: 0.9251526 | N20: 0.90250255 | O20: 2 | P20: 5125 | R20: RAINFED | S20: 2019 | T20: =IF(R20="IRRIGATED",IF(F20>=SCORES!I$6,1,0),"")
A21: 905.2145 | B21: 8.6 | C21: Class1 | D21: 31 | E21: 202 | F21: 288 | G21: 0 | J21: 220 | K21: Ong | L21: 1305 | M21: 0.89788855 | N21: 0.54220803 | O21: 1 | P21: 2991 | R21: RAINFED | S21: 2020 | T21: =IF(R21="IRRIGATED",IF(F21>=SCORES!I$6,1,0),"")
A22: 886.03519 | B22: 9.2 | C22: Class1 | D22: 31 | E22: 215 | F22: 268 | G22: 0 | J22: 208 | K22: Ong | L22: 92 | M22: 0.90312693 | N22: 0.90276147 | O22: 2 | P22: 4724 | R22: RAINFED | S22: 2020 | T22: =IF(R22="IRRIGATED",IF(F22>=SCORES!I$6,1,0),"")
A23: 889.40239 | B23: 10 | C23: Class1 | D23: 31 | E23: 142 | F23: 202 | G23: 0 | J23: 151 | K23: Ong | L23: 799 | M23: 0.90406316 | N23: 0.3594775 | O23: 1 | P23: 2492 | R23: RAINFED | S23: 2021 | T23: =IF(R23="IRRIGATED",IF(F23>=SCORES!I$6,1,0),"")
A24: 752.43329 | B24: 8.8 | C24: Class1 | D24: 31 | E24: 207 | F24: 292 | G24: 0 | J24: 199 | K24: Ong | L24: 88 | M24: 0.90892786 | N24: 0.90800831 | O24: 2 | P24: 4793 | R24: RAINFED | S24: 2021 | T24: =IF(R24="IRRIGATED",IF(F24>=SCORES!I$6,1,0),"")
A25: 791.58881 | B25: 6 | C25: Class1 | D25: 31 | E25: 206 | F25: 248 | G25: 0 | J25: 210 | K25: Ong | L25: 1193 | M25: 0.89504882 | N25: 0.49147649 | O25: 1 | P25: 3955 | R25: RAINFED | S25: 2022 | T25: =IF(R25="IRRIGATED",IF(F25>=SCORES!I$6,1,0),"")
A26: 935.35146 | B26: 7.5 | C26: Class1 | D26: 31 | E26: 204 | F26: 266 | G26: 0 | J26: 200 | K26: Ong | L26: 118 | M26: 0.92030224 | N26: 0.89486402 | O26: 2 | P26: 5466 | R26: RAINFED | S26: 2022 | T26: =IF(R26="IRRIGATED",IF(F26>=SCORES!I$6,1,0),"")
A27: 4.0898163 | B27: 0.2 | C27: Class1 | D27: 31 | E27: 239 | F27: 456 | G27: 0 | J27: 189 | K27: Ong | L27: 56 | O27: 3 | P27: 1963 | R27: RAINFED | S27: 2018 | T27: =IF(R27="IRRIGATED",IF(F27>=SCORES!I$6,1,0),"")
A28: 58.641947 | B28: 0.7 | C28: Class1 | D28: 31 | E28: 280 | F28: 425 | G28: 0 | J28: 229 | K28: Ong | L28: 116 | O28: 3 | P28: 3483 | R28: RAINFED | S28: 2019 | T28: =IF(R28="IRRIGATED",IF(F28>=SCORES!I$6,1,0),"")
A29: 13.050284 | B29: 0.6 | C29: Class1 | D29: 31 | E29: 182 | F29: 352 | G29: 0 | J29: 130 | K29: Ong | L29: 109 | O29: 3 | P29: 1443 | R29: RAINFED | S29: 2020 | T29: =IF(R29="IRRIGATED",IF(F29>=SCORES!I$6,1,0),"")
A30: 8.3266426 | B30: 0.3 | C30: Class1 | D30: 31 | E30: 182 | F30: 349 | G30: 0 | J30: 143 | K30: Ong | L30: 52 | O30: 3 | P30: 2325 | R30: RAINFED | S30: 2021 | T30: =IF(R30="IRRIGATED",IF(F30>=SCORES!I$6,1,0),"")
A31: 25.447043 | B31: 0.6 | C31: Class1 | D31: 31 | E31: 233 | F31: 369 | G31: 0 | J31: 157 | K31: Ong | L31: 45 | O31: 3 | P31: 1820 | R31: RAINFED | S31: 2022 | T31: =IF(R31="IRRIGATED",IF(F31>=SCORES!I$6,1,0),"")
A32: 1103.4964 | B32: 9.4 | C32: Class4 | D32: 34 | E32: 302 | F32: 358 | G32: 82 | H32: 0.12617248 | I32: 0.52725009 | J32: 218 | K32: Ong | L32: 1342 | M32: 0.92854274 | N32: 0.49314123 | O32: 1 | P32: 6380 | Q32: 7342 | R32: IRRIGATED | S32: 2018 | T32: =IF(R32="IRRIGATED",IF(F32>=SCORES!I$6,1,0),"") -> 1
A33: 1027.5863 | B33: 9.9 | C33: Class4 | D33: 34 | E33: 263 | F33: 336 | G33: 34 | H33: 0.040802421 | I33: 0.38562956 | J33: 224 | K33: Ong | L33: 57 | M33: 0.92393575 | N33: 0.90944058 | O33: 2 | P33: 7535 | Q33: 10404 | R33: IRRIGATED | S33: 2018 | T33: =IF(R33="IRRIGATED",IF(F33>=SCORES!I$6,1,0),"") -> 1
A34: 4306.1676 | B34: 33.3 | C34: Class4 | D34: 34 | E34: 266 | F34: 334 | G34: 34 | H34: 0.042562362 | I34: 0.54302631 | J34: 227 | K34: Ong | L34: 98 | M34: 0.9284987 | N34: 0.85365428 | O34: 2 | P34: 7819 | Q34: 10165 | R34: IRRIGATED | S34: 2019 | T34: =IF(R34="IRRIGATED",IF(F34>=SCORES!I$6,1,0),"") -> 1
A35: 3808.6613 | B35: 28.6 | C35: Class4 | D35: 34 | E35: 252 | F35: 336 | G35: 58 | H35: 0.19330612 | I35: 0.89136115 | J35: 190 | K35: Ong | L35: 1225 | M35: 0.93095675 | N35: 0.36360958 | O35: 1 | P35: 4294 | Q35: 5568 | R35: IRRIGATED | S35: 2019 | T35: =IF(R35="IRRIGATED",IF(F35>=SCORES!I$6,1,0),"") -> 1
A36: 364.76802 | B36: 3.8 | C36: Class4 | D36: 34 | E36: 285 | F36: 362 | G36: 33 | H36: 0.042734244 | I36: 0.44241038 | J36: 247 | K36: Ong | L36: 102 | M36: 0.92276157 | N36: 0.89632063 | O36: 2 | P36: 6758 | Q36: 8977 | R36: IRRIGATED | S36: 2020 | T36: =IF(R36="IRRIGATED",IF(F36>=SCORES!I$6,1,0),"") -> 1
A37: 348.25434 | B37: 3.3 | C37: Class4 | D37: 34 | E37: 321 | F37: 382 | G37: 93 | H37: 0.14251096 | I37: 0.48541482 | J37: 236 | K37: Ong | L37: 1460 | M37: 0.92059015 | N37: 0.6261363 | O37: 1 | P37: 4788 | Q37: 6114 | R37: IRRIGATED | S37: 2020 | T37: =IF(R37="IRRIGATED",IF(F37>=SCORES!I$6,1,0),"") -> 1
A38: 465.10642 | B38: 5.2 | C38: Class4 | D38: 34 | E38: 250 | F38: 316 | G38: 79 | H38: 0.21250162 | I38: 0.65831415 | J38: 170 | K38: Ong | L38: 1077 | M38: 0.9346708 | N38: 0.38468315 | O38: 1 | P38: 4091 | Q38: 5171 | R38: IRRIGATED | S38: 2021 | T38: =IF(R38="IRRIGATED",IF(F38>=SCORES!I$6,1,0),"") -> 1
A39: 638.98928 | B39: 7.4 | C39: Class4 | D39: 34 | E39: 271 | F39: 340 | G39: 36 | H39: 0.043937358 | I39: 0.4247904 | J39: 230 | K39: Ong | L39: 100 | M39: 0.93573419 | N39: 0.92303494 | O39: 2 | P39: 7065 | Q39: 9783 | R39: IRRIGATED | S39: 2021 | T39: =IF(R39="IRRIGATED",IF(F39>=SCORES!I$6,1,0),"") -> 1
A40: 1066.0128 | B40: 8.6 | C40: Class4 | D40: 34 | E40: 285 | F40: 364 | G40: 33 | H40: 0.04234814 | I40: 0.47410284 | J40: 247 | K40: Ong | L40: 129 | M40: 0.93422573 | N40: 0.90289978 | O40: 2 | P40: 8147 | Q40: 10511 | R40: IRRIGATED | S40: 2022 | T40: =IF(R40="IRRIGATED",IF(F40>=SCORES!I$6,1,0),"") -> 1
...

Sheet Indicators
B2: Scheme | C2: =Summary!C2 -> Ong | D2: =Summary!C2 -> Ong | E2: =Summary!C2 -> Ong | F2: =Summary!C2 -> Ong | K2: Annual | S2: Kharif | AX2: Rabi | CC2: Zaid
K3: Double Crop Kharif/Rabi | L3: Double Crop Rabi/Zaid | M3: Triple Crop | N3: Perennial Crops | O3: Kharif Crop | P3: Rabi Crop | Q3: Double Crop Kharif/Zaid | R3: Zaid Crop | S3: Cotton | T3: Paddy | U3: Maize | V3: Wheat | W3: Redgram | X3: Chickpea | Y3: Mustard | Z3: Jowar | AA3: Chili | AB3: Orchard | AC3: Groundnut | AD3: Potato | AE3: Sugarcane | AF3: Other Irrigated (High Water Intensive) | AG3: Other Irrigated (Less Water Intensive) | AH3: Other Rainfed | AI3: Class1 | AJ3: Class2 | AK3: Class3 | AL3: Class4 | AM3: Class5 | AN3: Class6 | AO3: Class7 | AP3: Class8 | AQ3: Class9 | AR3: Class10 | AS3: Class11 | AT3: Class12 | AU3: Class13 | AV3: Class14 | AW3: Class15 | AX3: Cotton | AY3: Paddy | AZ3: Maize | BA3: Wheat | BB3: Redgram | BC3: Chickpea | BD3: Mustard | BE3: Jowar | BF3: Chili | BG3: Orchard | BH3: Groundnut | BI3: Potato | BJ3: Sugarcane | BK3: Other Irrigated (High Water Intensive) | BL3: Other Irrigated (Less Water Intensive) | BM3: Other Rainfed | BN3: Class1 | BO3: Class2 | BP3: Class3 | BQ3: Class4 | BR3: Class5 | BS3: Class6 | BT3: Class7 | BU3: Class8 | BV3: Class9 | BW3: Class10 | BX3: Class11 | BY3: Class12 | BZ3: Class13 | CA3: Class14 | CB3: Class15 | CC3: Cotton | CD3: Paddy | CE3: Maize | CF3: Wheat | CG3: Redgram | CH3: Chickpea | CI3: Mustard | CJ3: Jowar | CK3: Chili | CL3: Orchard | CM3: Groundnut | CN3: Potato | CO3: Sugarcane | CP3: Other Irrigated (High Water Intensive) | CQ3: Other Irrigated (Less Water Intensive) | CR3: Other Rainfed | CS3: Class1 | CT3: Class2 | CU3: Class3 | CV3: Class4 | CW3: Class5 | CX3: Class6 | CY3: Class7 | CZ3: Class8 | DA3: Class9 | DB3: Class10 | DC3: Class11 | DD3: Class12 | DE3: Class13 | DF3: Class14 | DG3: Class15
A4: Command Area | B4: Total | C4: =Summary!$C4 -> 30837.7 | D4: =Summary!$C4 -> 30837.7 | E4: =Summary!$C4 -> 30837.7 | F4: =Summary!$C4 -> 30837.7 | J4: ID | K4: 1 | L4: 2 | M4: 3 | N4: 4 | O4: 5 | P4: 6 | Q4: 7 | R4: 8 | S4: 1 | T4: 2 | U4: 3 | V4: 4 | W4: 5 | X4: 6 | Y4: 7 | Z4: 8 | AA4: 9 | AB4: 10 | AC4: 11 | AD4: 12 | AE4: 13 | AF4: 14 | AG4: 15 | AH4: 16 | AI4: 17 | AJ4: 18 | AK4: 19 | AL4: 20 | AM4: 21 | AN4: 22 | AO4: 23 | AP4: 24 | AQ4: 25 | AR4: 40 | AS4: 41 | AT4: 42 | AU4: 43 | AV4: 44 | AW4: 45 | AX4: 1 | AY4: 2 | AZ4: 3 | BA4: 4 | BB4: 5 | BC4: 6 | BD4: 7 | BE4: 8 | BF4: 9 | BG4: 10 | BH4: 11 | BI4: 12 | BJ4: 13 | BK4: 14 | BL4: 15 | BM4: 17 | BN4: 31 | BO4: 32 | BP4: 33 | BQ4: 34 | BR4: 35 | BS4: 36 | BT4: 37 | BU4: 38 | BV4: 39 | BW4: 40 | BX4: 41 | BY4: 42 | BZ4: 43 | CA4: 44 | CB4: 45 | CC4: 1 | CD4: 2 | CE4: 3 | CF4: 4 | CG4: 5 | CH4: 6 | CI4: 7 | CJ4: 8 | CK4: 9 | CL4: 10 | CM4: 11 | CN4: 12 | CO4: 13 | CP4: 14 | CQ4: 15 | CR4: 17 | CS4: 31 | CT4: 32 | CU4: 33 | CV4: 34 | CW4: 35 | CX4: 36 | CY4: 37 | CZ4: 38 | DA4: 39 | DB4: 40 | DC4: 41 | DD4: 42 | DE4: 43 | DF4: 44 | DG4: 45
B5: CCA | C5: =Summary!$C3 -> 17276 | D5: =Summary!$C3 -> 17276 | E5: =Summary!$C3 -> 17276 | F5: =Summary!$C3 -> 17276 | J5: Cropping Intensity | K5: 2 | L5: 2 | M5: 3 | N5: 1 | O5: 1 | P5: 1 | Q5: 2 | R5: 1
C6: Kharif | D6: Rabi | E6: Zaid | F6: Annual
B7: Season | C7: 1 | D7: 2 | E7: 3 | F7: 0 | J7: Season | K7: 0 | L7: 0 | M7: 0 | N7: 0 | O7: 0 | P7: 0 | Q7: 0 | R7: 0 | S7: 1 | T7: 1 | U7: 1 | V7: 1 | W7: 1 | X7: 1 | Y7: 1 | Z7: 1 | AA7: 1 | AB7: 1 | AC7: 1 | AD7: 1 | AE7: 1 | AF7: 1 | AG7: 1 | AH7: 1 | AI7: 1 | AJ7: 1 | AK7: 1 | AL7: 1 | AM7: 1 | AN7: 1 | AO7: 1 | AP7: 1 | AQ7: 1 | AR7: 1 | AS7: 1 | AT7: 1 | AU7: 1 | AV7: 1 | AW7: 1 | AX7: 2 | AY7: 2 | AZ7: 2 | BA7: 2 | BB7: 2 | BC7: 2 | BD7: 2 | BE7: 2 | BF7: 2 | BG7: 2 | BH7: 2 | BI7: 2 | BJ7: 2 | BK7: 2 | BL7: 2 | BM7: 2 | BN7: 2 | BO7: 2 | BP7: 2 | BQ7: 2 | BR7: 2 | BS7: 2 | BT7: 2 | BU7: 2 | BV7: 2 | BW7: 2 | BX7: 2 | BY7: 2 | BZ7: 2 | CA7: 2 | CB7: 2 | CC7: 3 | CD7: 3 | CE7: 3 | CF7: 3 | CG7: 3 | CH7: 3 | CI7: 3 | CJ7: 3 | CK7: 3 | CL7: 3 | CM7: 3 | CN7: 3 | CO7: 3 | CP7: 3 | CQ7: 3 | CR7: 3 | CS7: 3 | CT7: 3 | CU7: 3 | CV7: 3 | CW7: 3 | CX7: 3 | CY7: 3 | CZ7: 3 | DA7: 3 | DB7: 3 | DC7: 3 | DD7: 3 | DE7: 3 | DF7: 3 | DG7: 3
A8: Cropped Area | B8: 2018 | C8: =IF(COUNTIFS('Data(perSeason,perCrop)'!$S:$S,Indicators!$B8)>0,SUMIFS('Data(perSeason,perCrop)'!$A:$A,'Data(perSeason,perCrop)'!$S:$S,Indicators!$B8,'Data(perSeason,perCrop)'!$O:$O,Indicators!C$7),"") -> 11758.214 | D8: =IF(COUNTIFS('Data(perSeason,perCrop)'!$S:$S,Indicators!$B8)>0,SUMIFS('Data(perSeason,perCrop)'!$A:$A,'Data(perSeason,perCrop)'!$S:$S,Indicators!$B8,'Data(perSeason,perCrop)'!$O:$O,Indicators!D$7),"") -> 10428.392 | E8: =IF(COUNTIFS('Data(perSeason,perCrop)'!$S:$S,Indicators!$B8)>0,SUMIFS('Data(perSeason,perCrop)'!$A:$A,'Data(perSeason,perCrop)'!$S:$S,Indicators!$B8,'Data(perSeason,perCrop)'!$O:$O,Indicators!E$7),"") -> 2632.3976 | F8: =IF(COUNTIFS('Data(perSeason,perCrop)'!$S:$S,Indicators!$B8)>0,SUMIFS('Data(perSeason,perCrop)'!$A:$A,'Data(perSeason,perCrop)'!$S:$S,Indicators!$B8,'Data(perSeason,perCrop)'!$O:$O,Indicators!F$7),"") -> 11794.087 | J8: ha | K8: =SUMIFS('Data(perSeason,perCrop)'!$A:$A,'Data(perSeason,perCrop)'!$S:$S,Indicators!$B8,'Data(perSeason,perCrop)'!$O:$O,Indicators!K$7,'Data(perSeason,perCrop)'!$C:$C,Indicators!K$3) -> 70.677874 | L8: =SUMIFS('Data(perSeason,perCrop)'!$A:$A,'Data(perSeason,perCrop)'!$S:$S,Indicators!$B8,'Data(perSeason,perCrop)'!$O:$O,Indicators!L$7,'Data(perSeason,perCrop)'!$C:$C,Indicators!L$3) -> 0 | M8: =SUMIFS('Data(perSeason,perCrop)'!$A:$A,'Data(perSeason,perCrop)'!$S:$S,Indicators!$B8,'Data(perSeason,perCrop)'!$O:$O,Indicators!M$7,'Data(perSeason,perCrop)'!$C:$C,Indicators!M$3) -> 0 | N8: =SUMIFS('Data(perSeason,perCrop)'!$A:$A,'Data(perSeason,perCrop)'!$S:$S,Indicators!$B8,'Data(perSeason,perCrop)'!$O:$O,Indicators!N$7,'Data(perSeason,perCrop)'!$C:$C,Indicators!N$3) -> 796.86923 | O8: =SUMIFS('Data(perSeason,perCrop)'!$A:$A,'Data(perSeason,perCrop)'!$S:$S,Indicators!$B8,'Data(perSeason,perCrop)'!$O:$O,Indicators!O$7,'Data(perSeason,perCrop)'!$C:$C,Indicators!O$3) -> 8677.5927 | P8: =SUMIFS('Data(perSeason,perCrop)'!$A:$A,'Data(perSeason,perCrop)'!$S:$S,Indicators!$B8,'Data(perSeason,perCrop)'!$O:$O,Indicators!P$7,'Data(perSeason,perCrop)'!$C:$C,Indicators!P$3) -> 0 | Q8: =SUMIFS('Data(perSeason,perCrop)'!$A:$A,'Data(perSeason,perCrop)'!$S:$S,Indicators!$B8,'Data(perSeason,perCrop)'!$O:$O,Indicators!Q$7,'Data(perSeason,perCrop)'!$C:$C,Indicators!Q$3) -> 2248.9474 | R8: =SUMIFS('Data(perSeason,perCrop)'!$A:$A,'Data(perSeason,perCrop)'!$S:$S,Indicators!$B8,'Data(perSeason,perCrop)'!$O:$O,Indicators!R$7,'Data(perSeason,perCrop)'!$C:$C,Indicators!R$3) -> 0 | ... DG8: =SUMIFS('Data(perSeason,perCrop)'!$A:$A,'Data(perSeason,perCrop)'!$S:$S,Indicators!$B8,'Data(perSeason,perCrop)'!$O:$O,Indicators!DG$7,'Data(perSeason,perCrop)'!$C:$C,Indicators!DG$3) -> 0
A9: hectares | B9: 2019 | C9: =IF(COUNTIFS('Data(perSeason,perCrop)'!$S:$S,Indicators!$B9)>0,SUMIFS('Data(perSeason,perCrop)'!$A:$A,'Data(perSeason,perCrop)'!$S:$S,Indicators!$B9,'Data(perSeason,perCrop)'!$O:$O,Indicators!C$7),"") -> 13338.71 | D9: =IF(COUNTIFS('Data(perSeason,perCrop)'!$S:$S,Indicators!$B9)>0,SUMIFS('Data(perSeason,perCrop)'!$A:$A,'Data(perSeason,perCrop)'!$S:$S,Indicators!$B9,'Data(perSeason,perCrop)'!$O:$O,Indicators!D$7),"") -> 12926.702 | E9: =IF(COUNTIFS('Data(perSeason,perCrop)'!$S:$S,Indicators!$B9)>0,SUMIFS('Data(perSeason,perCrop)'!$A:$A,'Data(perSeason,perCrop)'!$S:$S,Indicators!$B9,'Data(perSeason,perCrop)'!$O:$O,Indicators!E$7),"") -> 8239.616 | F9: =IF(COUNTIFS('Data(perSeason,perCrop)'!$S:$S,Indicators!$B9)>0,SUMIFS('Data(perSeason,perCrop)'!$A:$A,'Data(perSeason,perCrop)'!$S:$S,Indicators!$B9,'Data(perSeason,perCrop)'!$O:$O,Indicators!F$7),"") -> 13604.61 | J9: ha | K9: =SUMIFS('Data(perSeason,perCrop)'!$A:$A,'Data(perSeason,perCrop)'!$S:$S,Indicators!$B9,'Data(perSeason,perCrop)'!$O:$O,Indicators!K$7,'Data(perSeason,perCrop)'!$C:$C,Indicators!K$3) -> 118.67038 | L9: =SUMIFS('Data(perSeason,perCrop)'!$A:$A,'Data(perSeason,perCrop)'!$S:$S,Indicators!$B9,'Data(perSeason,perCrop)'!$O:$O,Indicators!L$7,'Data(perSeason,perCrop)'!$C:$C,Indicators!L$3) -> 49.024806 | M9: =SUMIFS('Data(perSeason,perCrop)'!$A:$A,'Data(perSeason,perCrop)'!$S:$S,Indicators!$B9,'Data(perSeason,perCrop)'!$O:$O,Indicators!M$7,'Data(perSeason,perCrop)'!$C:$C,Indicators!M$3) -> 107.79733 | N9: =SUMIFS('Data(perSeason,perCrop)'!$A:$A,'Data(perSeason,perCrop)'!$S:$S,Indicators!$B9,'Data(perSeason,perCrop)'!$O:$O,Indicators!N$7,'Data(perSeason,perCrop)'!$C:$C,Indicators!N$3) -> 3774.4034 | O9: =SUMIFS('Data(perSeason,perCrop)'!$A:$A,'Data(perSeason,perCrop)'!$S:$S,Indicators!$B9,'Data(perSeason,perCrop)'!$O:$O,Indicators!O$7,'Data(perSeason,perCrop)'!$C:$C,Indicators!O$3) -> 4537.6773 | P9: =SUMIFS('Data(perSeason,perCrop)'!$A:$A,'Data(perSeason,perCrop)'!$S:$S,Indicators!$B9,'Data(perSeason,perCrop)'!$O:$O,Indicators!P$7,'Data(perSeason,perCrop)'!$C:$C,Indicators!P$3) -> 120.27067 | Q9: =SUMIFS('Data(perSeason,perCrop)'!$A:$A,'Data(perSeason,perCrop)'!$S:$S,Indicators!$B9,'Data(perSeason,perCrop)'!$O:$O,Indicators!Q$7,'Data(perSeason,perCrop)'!$C:$C,Indicators!Q$3) -> 4888.8774 | R9: =SUMIFS('Data(perSeason,perCrop)'!$A:$A,'Data(perSeason,perCrop)'!$S:$S,Indicators!$B9,'Data(perSeason,perCrop)'!$O:$O,Indicators!R$7,'Data(perSeason,perCrop)'!$C:$C,Indicators!R$3) -> 7.8892189 | ... DG9: =SUMIFS('Data(perSeason,perCrop)'!$A:$A,'Data(perSeason,perCrop)'!$S:$S,Indicators!$B9,'Data(perSeason,perCrop)'!$O:$O,Indicators!DG$7,'Data(perSeason,perCrop)'!$C:$C,Indicators!DG$3) -> 0
B10: 2020 | C10: =IF(COUNTIFS('Data(perSeason,perCrop)'!$S:$S,Indicators!$B10)>0,SUMIFS('Data(perSeason,perCrop)'!$A:$A,'Data(perSeason,perCrop)'!$S:$S,Indicators!$B10,'Data(perSeason,perCrop)'!$O:$O,Indicators!C$7),"") -> 10489.32 | D10: =IF(COUNTIFS('Data(perSeason,perCrop)'!$S:$S,Indicators!$B10)>0,SUMIFS('Data(perSeason,perCrop)'!$A:$A,'Data(perSeason,perCrop)'!$S:$S,Indicators!$B10,'Data(perSeason,perCrop)'!$O:$O,Indicators!D$7),"") -> 9622.138 | E10: =IF(COUNTIFS('Data(perSeason,perCrop)'!$S:$S,Indicators!$B10)>0,SUMIFS('Data(perSeason,perCrop)'!$A:$A,'Data(perSeason,perCrop)'!$S:$S,Indicators!$B10,'Data(perSeason,perCrop)'!$O:$O,Indicators!E$7),"") -> 2310.9205 | F10: =IF(COUNTIFS('Data(perSeason,perCrop)'!$S:$S,Indicators!$B10)>0,SUMIFS('Data(perSeason,perCrop)'!$A:$A,'Data(perSeason,perCrop)'!$S:$S,Indicators!$B10,'Data(perSeason,perCrop)'!$O:$O,Indicators!F$7),"") -> 10557.426 | J10: ha | K10: =SUMIFS('Data(perSeason,perCrop)'!$A:$A,'Data(perSeason,perCrop)'!$S:$S,Indicators!$B10,'Data(perSeason,perCrop)'!$O:$O,Indicators!K$7,'Data(perSeason,perCrop)'!$C:$C,Indicators!K$3) -> 59.597834 | L10: =SUMIFS('Data(perSeason,perCrop)'!$A:$A,'Data(perSeason,perCrop)'!$S:$S,Indicators!$B10,'Data(perSeason,perCrop)'!$O:$O,Indicators!L$7,'Data(perSeason,perCrop)'!$C:$C,Indicators!L$3) -> 15.666136 | M10: =SUMIFS('Data(perSeason,perCrop)'!$A:$A,'Data(perSeason,perCrop)'!$S:$S,Indicators!$B10,'Data(perSeason,perCrop)'!$O:$O,Indicators!M$7,'Data(perSeason,perCrop)'!$C:$C,Indicators!M$3) -> 6.7832797 | N10: =SUMIFS('Data(perSeason,perCrop)'!$A:$A,'Data(perSeason,perCrop)'!$S:$S,Indicators!$B10,'Data(perSeason,perCrop)'!$O:$O,Indicators!N$7,'Data(perSeason,perCrop)'!$C:$C,Indicators!N$3) -> 306.93799 | O10: =SUMIFS('Data(perSeason,perCrop)'!$A:$A,'Data(perSeason,perCrop)'!$S:$S,Indicators!$B10,'Data(perSeason,perCrop)'!$O:$O,Indicators!O$7,'Data(perSeason,perCrop)'!$C:$C,Indicators!O$3) -> 7898.0791 | P10: =SUMIFS('Data(perSeason,perCrop)'!$A:$A,'Data(perSeason,perCrop)'!$S:$S,Indicators!$B10,'Data(perSeason,perCrop)'!$O:$O,Indicators!P$7,'Data(perSeason,perCrop)'!$C:$C,Indicators!P$3) -> 13.218432 | Q10: =SUMIFS('Data(perSeason,perCrop)'!$A:$A,'Data(perSeason,perCrop)'!$S:$S,Indicators!$B10,'Data(perSeason,perCrop)'!$O:$O,Indicators!Q$7,'Data(perSeason,perCrop)'!$C:$C,Indicators!Q$3) -> 2257.1429 | R10: =SUMIFS('Data(perSeason,perCrop)'!$A:$A,'Data(perSeason,perCrop)'!$S:$S,Indicators!$B10,'Data(perSeason,perCrop)'!$O:$O,Indicators!R$7,'Data(perSeason,perCrop)'!$C:$C,Indicators!R$3) -> 0 | ... DG10: =SUMIFS('Data(perSeason,perCrop)'!$A:$A,'Data(perSeason,perCrop)'!$S:$S,Indicators!$B10,'Data(perSeason,perCrop)'!$O:$O,Indicators!DG$7,'Data(perSeason,perCrop)'!$C:$C,Indicators!DG$3) -> 0
B11: 2021 | C11: =IF(COUNTIFS('Data(perSeason,perCrop)'!$S:$S,Indicators!$B11)>0,SUMIFS('Data(perSeason,perCrop)'!$A:$A,'Data(perSeason,perCrop)'!$S:$S,Indicators!$B11,'Data(perSeason,perCrop)'!$O:$O,Indicators!C$7),"") -> 8866.3267 | D11: =IF(COUNTIFS('Data(perSeason,perCrop)'!$S:$S,Indicators!$B11)>0,SUMIFS('Data(perSeason,perCrop)'!$A:$A,'Data(perSeason,perCrop)'!$S:$S,Indicators!$B11,'Data(perSeason,perCrop)'!$O:$O,Indicators!D$7),"") -> 8586.6883 | E11: =IF(COUNTIFS('Data(perSeason,perCrop)'!$S:$S,Indicators!$B11)>0,SUMIFS('Data(perSeason,perCrop)'!$A:$A,'Data(perSeason,perCrop)'!$S:$S,Indicators!$B11,'Data(perSeason,perCrop)'!$O:$O,Indicators!E$7),"") -> 2524.5384 | F11: =IF(COUNTIFS('Data(perSeason,perCrop)'!$S:$S,Indicators!$B11)>0,SUMIFS('Data(perSeason,perCrop)'!$A:$A,'Data(perSeason,perCrop)'!$S:$S,Indicators!$B11,'Data(perSeason,perCrop)'!$O:$O,Indicators!F$7),"") -> 9023.1314 | J11: ha | K11: =SUMIFS('Data(perSeason,perCrop)'!$A:$A,'Data(perSeason,perCrop)'!$S:$S,Indicators!$B11,'Data(perSeason,perCrop)'!$O:$O,Indicators!K$7,'Data(perSeason,perCrop)'!$C:$C,Indicators!K$3) -> 114.53169 | L11: =SUMIFS('Data(perSeason,perCrop)'!$A:$A,'Data(perSeason,perCrop)'!$S:$S,Indicators!$B11,'Data(perSeason,perCrop)'!$O:$O,Indicators!L$7,'Data(perSeason,perCrop)'!$C:$C,Indicators!L$3) -> 14.3836 | M11: =SUMIFS('Data(perSeason,perCrop)'!$A:$A,'Data(perSeason,perCrop)'!$S:$S,Indicators!$B11,'Data(perSeason,perCrop)'!$O:$O,Indicators!M$7,'Data(perSeason,perCrop)'!$C:$C,Indicators!M$3) -> 11.209214 | N11: =SUMIFS('Data(perSeason,perCrop)'!$A:$A,'Data(perSeason,perCrop)'!$S:$S,Indicators!$B11,'Data(perSeason,perCrop)'!$O:$O,Indicators!N$7,'Data(perSeason,perCrop)'!$C:$C,Indicators!N$3) -> 648.99691 | O11: =SUMIFS('Data(perSeason,perCrop)'!$A:$A,'Data(perSeason,perCrop)'!$S:$S,Indicators!$B11,'Data(perSeason,perCrop)'!$O:$O,Indicators!O$7,'Data(perSeason,perCrop)'!$C:$C,Indicators!O$3) -> 6029.0039 | P11: =SUMIFS('Data(perSeason,perCrop)'!$A:$A,'Data(perSeason,perCrop)'!$S:$S,Indicators!$B11,'Data(perSeason,perCrop)'!$O:$O,Indicators!P$7,'Data(perSeason,perCrop)'!$C:$C,Indicators!P$3) -> 82.084902 | Q11: =SUMIFS('Data(perSeason,perCrop)'!$A:$A,'Data(perSeason,perCrop)'!$S:$S,Indicators!$B11,'Data(perSeason,perCrop)'!$O:$O,Indicators!Q$7,'Data(perSeason,perCrop)'!$C:$C,Indicators!Q$3) -> 2122.9211 | R11: =SUMIFS('Data(perSeason,perCrop)'!$A:$A,'Data(perSeason,perCrop)'!$S:$S,Indicators!$B11,'Data(perSeason,perCrop)'!$O:$O,Indicators!R$7,'Data(perSeason,perCrop)'!$C:$C,Indicators!R$3) -> 0 | ... DG11: =SUMIFS('Data(perSeason,perCrop)'!$A:$A,'Data(perSeason,perCrop)'!$S:$S,Indicators!$B11,'Data(perSeason,perCrop)'!$O:$O,Indicators!DG$7,'Data(perSeason,perCrop)'!$C:$C,Indicators!DG$3) -> 0
B12: 2022 | C12: =IF(COUNTIFS('Data(perSeason,perCrop)'!$S:$S,Indicators!$B12)>0,SUMIFS('Data(perSeason,perCrop)'!$A:$A,'Data(perSeason,perCrop)'!$S:$S,Indicators!$B12,'Data(perSeason,perCrop)'!$O:$O,Indicators!C$7),"") -> 13269.491 | D12: =IF(COUNTIFS('Data(perSeason,perCrop)'!$S:$S,Indicators!$B12)>0,SUMIFS('Data(perSeason,perCrop)'!$A:$A,'Data(perSeason,perCrop)'!$S:$S,Indicators!$B12,'Data(perSeason,perCrop)'!$O:$O,Indicators!D$7),"") -> 12447.907 | E12: =IF(COUNTIFS('Data(perSeason,perCrop)'!$S:$S,Indicators!$B12)>0,SUMIFS('Data(perSeason,perCrop)'!$A:$A,'Data(perSeason,perCrop)'!$S:$S,Indicators!$B12,'Data(perSeason,perCrop)'!$O:$O,Indicators!E$7),"") -> 4583.7569 | F12: =IF(COUNTIFS('Data(perSeason,perCrop)'!$S:$S,Indicators!$B12)>0,SUMIFS('Data(perSeason,perCrop)'!$A:$A,'Data(perSeason,perCrop)'!$S:$S,Indicators!$B12,'Data(perSeason,perCrop)'!$O:$O,Indicators!F$7),"") -> 13322.803 | J12: ha | K12: =SUMIFS('Data(perSeason,perCrop)'!$A:$A,'Data(perSeason,perCrop)'!$S:$S,Indicators!$B12,'Data(perSeason,perCrop)'!$O:$O,Indicators!K$7,'Data(perSeason,perCrop)'!$C:$C,Indicators!K$3) -> 11.589767 | L12: =SUMIFS('Data(perSeason,perCrop)'!$A:$A,'Data(perSeason,perCrop)'!$S:$S,Indicators!$B12,'Data(perSeason,perCrop)'!$O:$O,Indicators!L$7,'Data(perSeason,perCrop)'!$C:$C,Indicators!L$3) -> 0 | M12: =SUMIFS('Data(perSeason,perCrop)'!$A:$A,'Data(perSeason,perCrop)'!$S:$S,Indicators!$B12,'Data(perSeason,perCrop)'!$O:$O,Indicators!M$7,'Data(perSeason,perCrop)'!$C:$C,Indicators!M$3) -> 0 | N12: =SUMIFS('Data(perSeason,perCrop)'!$A:$A,'Data(perSeason,perCrop)'!$S:$S,Indicators!$B12,'Data(perSeason,perCrop)'!$O:$O,Indicators!N$7,'Data(perSeason,perCrop)'!$C:$C,Indicators!N$3) -> 708.97698 | O12: =SUMIFS('Data(perSeason,perCrop)'!$A:$A,'Data(perSeason,perCrop)'!$S:$S,Indicators!$B12,'Data(perSeason,perCrop)'!$O:$O,Indicators!O$7,'Data(perSeason,perCrop)'!$C:$C,Indicators!O$3) -> 8199.9696 | P12: =SUMIFS('Data(perSeason,perCrop)'!$A:$A,'Data(perSeason,perCrop)'!$S:$S,Indicators!$B12,'Data(perSeason,perCrop)'!$O:$O,Indicators!P$7,'Data(perSeason,perCrop)'!$C:$C,Indicators!P$3) -> 0 | Q12: =SUMIFS('Data(perSeason,perCrop)'!$A:$A,'Data(perSeason,perCrop)'!$S:$S,Indicators!$B12,'Data(perSeason,perCrop)'!$O:$O,Indicators!Q$7,'Data(perSeason,perCrop)'!$C:$C,Indicators!Q$3) -> 4402.2663 | R12: =SUMIFS('Data(perSeason,perCrop)'!$A:$A,'Data(perSeason,perCrop)'!$S:$S,Indicators!$B12,'Data(perSeason,perCrop)'!$O:$O,Indicators!R$7,'Data(perSeason,perCrop)'!$C:$C,Indicators!R$3) -> 0 | ... DG12: =SUMIFS('Data(perSeason,perCrop)'!$A:$A,'Data(perSeason,perCrop)'!$S:$S,Indicators!$B12,'Data(perSeason,perCrop)'!$O:$O,Indicators!DG$7,'Data(perSeason,perCrop)'!$C:$C,Indicators!DG$3) -> 0
B13: AVERAGE | C13: =AVERAGE(C8:C12) -> 11544.413 | D13: =AVERAGE(D8:D12) -> 10802.366 | E13: =AVERAGE(E8:E12) -> 4058.2459 | F13: =AVERAGE(F8:F12) -> 11660.411 | J13: ha | K13: =AVERAGE(K8:K12) -> 75.013509 | L13: =AVERAGE(L8:L12) -> 15.814908 | M13: =AVERAGE(M8:M12) -> 25.157964 | N13: =AVERAGE(N8:N12) -> 1247.2369 | O13: =AVERAGE(O8:O12) -> 7068.4645 | P13: =AVERAGE(P8:P12) -> 43.114801 | Q13: =AVERAGE(Q8:Q12) -> 3184.031 | R13: =AVERAGE(R8:R12) -> 1.5778438 | ... DG13: =AVERAGE(DG8:DG12) -> 0
K14: =K13/SUM($K13:$R13) -> 0.0064331785 | L14: =L13/SUM($K13:$R13) -> 0.0013562907 | M14: =M13/SUM($K13:$R13) -> 0.0021575537 | N14: =N13/SUM($K13:$R13) -> 0.10696337 | O14: =O13/SUM($K13:$R13) -> 0.6061934 | P14: =P13/SUM($K13:$R13) -> 0.0036975368 | Q14: =Q13/SUM($K13:$R13) -> 0.27306335 | R14: =R13/SUM($K13:$R13) -> 0.0001353163 | S14: =S13/SUM($S13:$AH13) -> 0 | T14: =T13/SUM($S13:$AH13) -> 0.92281459 | U14: =U13/SUM($S13:$AH13) -> 0 | V14: =V13/SUM($S13:$AH13) -> 0 | W14: =W13/SUM($S13:$AH13) -> 0 | X14: =X13/SUM($S13:$AH13) -> 0 | Y14: =Y13/SUM($S13:$AH13) -> 0 | Z14: =Z13/SUM($S13:$AH13) -> 0 | ... AW14: =AW13/SUM($S13:$AH13) -> 0 | AX14: =AX13/SUM($AY13:$BM13) -> 0 | AY14: =AY13/SUM($AY13:$BM13) -> 0.98020071 | AZ14: =AZ13/SUM($AY13:$BM13) -> 0 | BA14: =BA13/SUM($AY13:$BM13) -> 0 | BB14: =BB13/SUM($AY13:$BM13) -> 0 | BC14: =BC13/SUM($AY13:$BM13) -> 0 | BD14: =BD13/SUM($AY13:$BM13) -> 0 | BE14: =BE13/SUM($AY13:$BM13) -> 0 | ... CB14: =CB13/SUM($AY13:$BM13) -> 0 | CC14: =CC13/SUM($CD13:$CR13) -> 0 | CD14: =CD13/SUM($CD13:$CR13) -> 0 | CE14: =CE13/SUM($CD13:$CR13) -> 0 | CF14: =CF13/SUM($CD13:$CR13) -> 0 | CG14: =CG13/SUM($CD13:$CR13) -> 0 | CH14: =CH13/SUM($CD13:$CR13) -> 0 | CI14: =CI13/SUM($CD13:$CR13) -> 0 | CJ14: =CJ13/SUM($CD13:$CR13) -> 0 | ... DG14: =DG13/SUM($CD13:$CR13) -> 0
A15: Irrigated Area | B15: 2018 | C15: =IF(COUNTIFS('Data(perSeason,perCrop)'!$S:$S,Indicators!$B15)>0,SUMIFS('Data(perSeason,perCrop)'!$A:$A,'Data(perSeason,perCrop)'!$S:$S,Indicators!$B15,'Data(perSeason,perCrop)'!$O:$O,Indicators!C$7,'Data(perSeason,perCrop)'!$R:$R,"IRRIGATED"),"") -> 7689.8545 | D15: =IF(COUNTIFS('Data(perSeason,perCrop)'!$S:$S,Indicators!$B15)>0,SUMIFS('Data(perSeason,perCrop)'!$A:$A,'Data(perSeason,perCrop)'!$S:$S,Indicators!$B15,'Data(perSeason,perCrop)'!$O:$O,Indicators!D$7,'Data(perSeason,perCrop)'!$R:$R,"IRRIGATED"),"") -> 7568.4326 | E15: =IF(COUNTIFS('Data(perSeason,perCrop)'!$S:$S,Indicators!$B15)>0,SUMIFS('Data(perSeason,perCrop)'!$A:$A,'Data(perSeason,perCrop)'!$S:$S,Indicators!$B15,'Data(perSeason,perCrop)'!$O:$O,Indicators!E$7,'Data(perSeason,perCrop)'!$R:$R,"IRRIGATED"),"") -> 2487.8555 | F15: =IF(COUNTIFS('Data(perSeason,perCrop)'!$S:$S,Indicators!$B15)>0,SUM(K15:R15),"") -> 9367.697 | J15: ha | K15: =SUMIFS('Data(perSeason,perCrop)'!$A:$A,'Data(perSeason,perCrop)'!$S:$S,Indicators!$B15,'Data(perSeason,perCrop)'!$O:$O,Indicators!K$7,'Data(perSeason,perCrop)'!$C:$C,Indicators!K$3,'Data(perSeason,perCrop)'!$R:$R,"IRRIGATED") -> 59.843344 | L15: =SUMIFS('Data(perSeason,perCrop)'!$A:$A,'Data(perSeason,perCrop)'!$S:$S,Indicators!$B15,'Data(perSeason,perCrop)'!$O:$O,Indicators!L$7,'Data(perSeason,perCrop)'!$C:$C,Indicators!L$3,'Data(perSeason,perCrop)'!$R:$R,"IRRIGATED") -> 0 | M15: =SUMIFS('Data(perSeason,perCrop)'!$A:$A,'Data(perSeason,perCrop)'!$S:$S,Indicators!$B15,'Data(perSeason,perCrop)'!$O:$O,Indicators!M$7,'Data(perSeason,perCrop)'!$C:$C,Indicators!M$3,'Data(perSeason,perCrop)'!$R:$R,"IRRIGATED") -> 0 | N15: =SUMIFS('Data(perSeason,perCrop)'!$A:$A,'Data(perSeason,perCrop)'!$S:$S,Indicators!$B15,'Data(perSeason,perCrop)'!$O:$O,Indicators!N$7,'Data(perSeason,perCrop)'!$C:$C,Indicators!N$3,'Data(perSeason,perCrop)'!$R:$R,"IRRIGATED") -> 674.8299 | O15: =SUMIFS('Data(perSeason,perCrop)'!$A:$A,'Data(perSeason,perCrop)'!$S:$S,Indicators!$B15,'Data(perSeason,perCrop)'!$O:$O,Indicators!O$7,'Data(perSeason,perCrop)'!$C:$C,Indicators!O$3,'Data(perSeason,perCrop)'!$R:$R,"IRRIGATED") -> 6429.0186 | P15: =SUMIFS('Data(perSeason,perCrop)'!$A:$A,'Data(perSeason,perCrop)'!$S:$S,Indicators!$B15,'Data(perSeason,perCrop)'!$O:$O,Indicators!P$7,'Data(perSeason,perCrop)'!$C:$C,Indicators!P$3,'Data(perSeason,perCrop)'!$R:$R,"IRRIGATED") -> 0 | Q15: =SUMIFS('Data(perSeason,perCrop)'!$A:$A,'Data(perSeason,perCrop)'!$S:$S,Indicators!$B15,'Data(perSeason,perCrop)'!$O:$O,Indicators!Q$7,'Data(perSeason,perCrop)'!$C:$C,Indicators!Q$3,'Data(perSeason,perCrop)'!$R:$R,"IRRIGATED") -> 2204.0052 | R15: =SUMIFS('Data(perSeason,perCrop)'!$A:$A,'Data(perSeason,perCrop)'!$S:$S,Indicators!$B15,'Data(perSeason,perCrop)'!$O:$O,Indicators!R$7,'Data(perSeason,perCrop)'!$C:$C,Indicators!R$3,'Data(perSeason,perCrop)'!$R:$R,"IRRIGATED") -> 0 | ... DG15: =SUMIFS('Data(perSeason,perCrop)'!$A:$A,'Data(perSeason,perCrop)'!$S:$S,Indicators!$B15,'Data(perSeason,perCrop)'!$O:$O,Indicators!DG$7,'Data(perSeason,perCrop)'!$C:$C,Indicators!DG$3,'Data(perSeason,perCrop)'!$R:$R,"IRRIGATED") -> 0
A16: hectares | B16: 2019 | C16: =IF(COUNTIFS('Data(perSeason,perCrop)'!$S:$S,Indicators!$B16)>0,SUMIFS('Data(perSeason,perCrop)'!$A:$A,'Data(perSeason,perCrop)'!$S:$S,Indicators!$B16,'Data(perSeason,perCrop)'!$O:$O,Indicators!C$7,'Data(perSeason,perCrop)'!$R:$R,"IRRIGATED"),"") -> 6859.2281 | D16: =IF(COUNTIFS('Data(perSeason,perCrop)'!$S:$S,Indicators!$B16)>0,SUMIFS('Data(perSeason,perCrop)'!$A:$A,'Data(perSeason,perCrop)'!$S:$S,Indicators!$B16,'Data(perSeason,perCrop)'!$O:$O,Indicators!D$7,'Data(perSeason,perCrop)'!$R:$R,"IRRIGATED"),"") -> 7941.8235 | E16: =IF(COUNTIFS('Data(perSeason,perCrop)'!$S:$S,Indicators!$B16)>0,SUMIFS('Data(perSeason,perCrop)'!$A:$A,'Data(perSeason,perCrop)'!$S:$S,Indicators!$B16,'Data(perSeason,perCrop)'!$O:$O,Indicators!E$7,'Data(perSeason,perCrop)'!$R:$R,"IRRIGATED"),"") -> 7379.0889 | F16: =IF(COUNTIFS('Data(perSeason,perCrop)'!$S:$S,Indicators!$B16)>0,SUM(K16:R16),"") -> 10483.216 | J16: ha | K16: =SUMIFS('Data(perSeason,perCrop)'!$A:$A,'Data(perSeason,perCrop)'!$S:$S,Indicators!$B16,'Data(perSeason,perCrop)'!$O:$O,Indicators!K$7,'Data(perSeason,perCrop)'!$C:$C,Indicators!K$3,'Data(perSeason,perCrop)'!$R:$R,"IRRIGATED") -> 75.894637 | L16: =SUMIFS('Data(perSeason,perCrop)'!$A:$A,'Data(perSeason,perCrop)'!$S:$S,Indicators!$B16,'Data(perSeason,perCrop)'!$O:$O,Indicators!L$7,'Data(perSeason,perCrop)'!$C:$C,Indicators!L$3,'Data(perSeason,perCrop)'!$R:$R,"IRRIGATED") -> 49.024806 | M16: =SUMIFS('Data(perSeason,perCrop)'!$A:$A,'Data(perSeason,perCrop)'!$S:$S,Indicators!$B16,'Data(perSeason,perCrop)'!$O:$O,Indicators!M$7,'Data(perSeason,perCrop)'!$C:$C,Indicators!M$3,'Data(perSeason,perCrop)'!$R:$R,"IRRIGATED") -> 107.79733 | N16: =SUMIFS('Data(perSeason,perCrop)'!$A:$A,'Data(perSeason,perCrop)'!$S:$S,Indicators!$B16,'Data(perSeason,perCrop)'!$O:$O,Indicators!N$7,'Data(perSeason,perCrop)'!$C:$C,Indicators!N$3,'Data(perSeason,perCrop)'!$R:$R,"IRRIGATED") -> 3035.494 | O16: =SUMIFS('Data(perSeason,perCrop)'!$A:$A,'Data(perSeason,perCrop)'!$S:$S,Indicators!$B16,'Data(perSeason,perCrop)'!$O:$O,Indicators!O$7,'Data(perSeason,perCrop)'!$C:$C,Indicators!O$3,'Data(perSeason,perCrop)'!$R:$R,"IRRIGATED") -> 2517.5209 | P16: =SUMIFS('Data(perSeason,perCrop)'!$A:$A,'Data(perSeason,perCrop)'!$S:$S,Indicators!$B16,'Data(perSeason,perCrop)'!$O:$O,Indicators!P$7,'Data(perSeason,perCrop)'!$C:$C,Indicators!P$3,'Data(perSeason,perCrop)'!$R:$R,"IRRIGATED") -> 80.534693 | Q16: =SUMIFS('Data(perSeason,perCrop)'!$A:$A,'Data(perSeason,perCrop)'!$S:$S,Indicators!$B16,'Data(perSeason,perCrop)'!$O:$O,Indicators!Q$7,'Data(perSeason,perCrop)'!$C:$C,Indicators!Q$3,'Data(perSeason,perCrop)'!$R:$R,"IRRIGATED") -> 4609.0601 | R16: =SUMIFS('Data(perSeason,perCrop)'!$A:$A,'Data(perSeason,perCrop)'!$S:$S,Indicators!$B16,'Data(perSeason,perCrop)'!$O:$O,Indicators!R$7,'Data(perSeason,perCrop)'!$C:$C,Indicators!R$3,'Data(perSeason,perCrop)'!$R:$R,"IRRIGATED") -> 7.8892189 | ... DG16: =SUMIFS('Data(perSeason,perCrop)'!$A:$A,'Data(perSeason,perCrop)'!$S:$S,Indicators!$B16,'Data(perSeason,perCrop)'!$O:$O,Indicators!DG$7,'Data(perSeason,perCrop)'!$C:$C,Indicators!DG$3,'Data(perSeason,perCrop)'!$R:$R,"IRRIGATED") -> 0
B17: 2020 | C17: =IF(COUNTIFS('Data(perSeason,perCrop)'!$S:$S,Indicators!$B17)>0,SUMIFS('Data(perSeason,perCrop)'!$A:$A,'Data(perSeason,perCrop)'!$S:$S,Indicators!$B17,'Data(perSeason,perCrop)'!$O:$O,Indicators!C$7,'Data(perSeason,perCrop)'!$R:$R,"IRRIGATED"),"") -> 3887.5939 | D17: =IF(COUNTIFS('Data(perSeason,perCrop)'!$S:$S,Indicators!$B17)>0,SUMIFS('Data(perSeason,perCrop)'!$A:$A,'Data(perSeason,perCrop)'!$S:$S,Indicators!$B17,'Data(perSeason,perCrop)'!$O:$O,Indicators!D$7,'Data(perSeason,perCrop)'!$R:$R,"IRRIGATED"),"") -> 4594.9125 | E17: =IF(COUNTIFS('Data(perSeason,perCrop)'!$S:$S,Indicators!$B17)>0,SUMIFS('Data(perSeason,perCrop)'!$A:$A,'Data(perSeason,perCrop)'!$S:$S,Indicators!$B17,'Data(perSeason,perCrop)'!$O:$O,Indicators!E$7,'Data(perSeason,perCrop)'!$R:$R,"IRRIGATED"),"") -> 2222.2352 | F17: =IF(COUNTIFS('Data(perSeason,perCrop)'!$S:$S,Indicators!$B17)>0,SUM(K17:R17),"") -> 6289.0048 | J17: ha | K17: =SUMIFS('Data(perSeason,perCrop)'!$A:$A,'Data(perSeason,perCrop)'!$S:$S,Indicators!$B17,'Data(perSeason,perCrop)'!$O:$O,Indicators!K$7,'Data(perSeason,perCrop)'!$C:$C,Indicators!K$3,'Data(perSeason,perCrop)'!$R:$R,"IRRIGATED") -> 25.360404 | L17: =SUMIFS('Data(perSeason,perCrop)'!$A:$A,'Data(perSeason,perCrop)'!$S:$S,Indicators!$B17,'Data(perSeason,perCrop)'!$O:$O,Indicators!L$7,'Data(perSeason,perCrop)'!$C:$C,Indicators!L$3,'Data(perSeason,perCrop)'!$R:$R,"IRRIGATED") -> 15.666136 | M17: =SUMIFS('Data(perSeason,perCrop)'!$A:$A,'Data(perSeason,perCrop)'!$S:$S,Indicators!$B17,'Data(perSeason,perCrop)'!$O:$O,Indicators!M$7,'Data(perSeason,perCrop)'!$C:$C,Indicators!M$3,'Data(perSeason,perCrop)'!$R:$R,"IRRIGATED") -> 6.7832797 | N17: =SUMIFS('Data(perSeason,perCrop)'!$A:$A,'Data(perSeason,perCrop)'!$S:$S,Indicators!$B17,'Data(perSeason,perCrop)'!$O:$O,Indicators!N$7,'Data(perSeason,perCrop)'!$C:$C,Indicators!N$3,'Data(perSeason,perCrop)'!$R:$R,"IRRIGATED") -> 251.17421 | O17: =SUMIFS('Data(perSeason,perCrop)'!$A:$A,'Data(perSeason,perCrop)'!$S:$S,Indicators!$B17,'Data(perSeason,perCrop)'!$O:$O,Indicators!O$7,'Data(perSeason,perCrop)'!$C:$C,Indicators!O$3,'Data(perSeason,perCrop)'!$R:$R,"IRRIGATED") -> 3835.7191 | P17: =SUMIFS('Data(perSeason,perCrop)'!$A:$A,'Data(perSeason,perCrop)'!$S:$S,Indicators!$B17,'Data(perSeason,perCrop)'!$O:$O,Indicators!P$7,'Data(perSeason,perCrop)'!$C:$C,Indicators!P$3,'Data(perSeason,perCrop)'!$R:$R,"IRRIGATED") -> 0 | Q17: =SUMIFS('Data(perSeason,perCrop)'!$A:$A,'Data(perSeason,perCrop)'!$S:$S,Indicators!$B17,'Data(perSeason,perCrop)'!$O:$O,Indicators!Q$7,'Data(perSeason,perCrop)'!$C:$C,Indicators!Q$3,'Data(perSeason,perCrop)'!$R:$R,"IRRIGATED") -> 2154.3017 | R17: =SUMIFS('Data(perSeason,perCrop)'!$A:$A,'Data(perSeason,perCrop)'!$S:$S,Indicators!$B17,'Data(perSeason,perCrop)'!$O:$O,Indicators!R$7,'Data(perSeason,perCrop)'!$C:$C,Indicators!R$3,'Data(perSeason,perCrop)'!$R:$R,"IRRIGATED") -> 0 | ... DG17: =SUMIFS('Data(perSeason,perCrop)'!$A:$A,'Data(perSeason,perCrop)'!$S:$S,Indicators!$B17,'Data(perSeason,perCrop)'!$O:$O,Indicators!DG$7,'Data(perSeason,perCrop)'!$C:$C,Indicators!DG$3,'Data(perSeason,perCrop)'!$R:$R,"IRRIGATED") -> 0
B18: 2021 | C18: =IF(COUNTIFS('Data(perSeason,perCrop)'!$S:$S,Indicators!$B18)>0,SUMIFS('Data(perSeason,perCrop)'!$A:$A,'Data(perSeason,perCrop)'!$S:$S,Indicators!$B18,'Data(perSeason,perCrop)'!$O:$O,Indicators!C$7,'Data(perSeason,perCrop)'!$R:$R,"IRRIGATED"),"") -> 4180.9654 | D18: =IF(COUNTIFS('Data(perSeason,perCrop)'!$S:$S,Indicators!$B18)>0,SUMIFS('Data(perSeason,perCrop)'!$A:$A,'Data(perSeason,perCrop)'!$S:$S,Indicators!$B18,'Data(perSeason,perCrop)'!$O:$O,Indicators!D$7,'Data(perSeason,perCrop)'!$R:$R,"IRRIGATED"),"") -> 5951.5333 | E18: =IF(COUNTIFS('Data(perSeason,perCrop)'!$S:$S,Indicators!$B18)>0,SUMIFS('Data(perSeason,perCrop)'!$A:$A,'Data(perSeason,perCrop)'!$S:$S,Indicators!$B18,'Data(perSeason,perCrop)'!$O:$O,Indicators!E$7,'Data(perSeason,perCrop)'!$R:$R,"IRRIGATED"),"") -> 2355.2261 | F18: =IF(COUNTIFS('Data(perSeason,perCrop)'!$S:$S,Indicators!$B18)>0,SUM(K18:R18),"") -> 6836.0164 | J18: ha | K18: =SUMIFS('Data(perSeason,perCrop)'!$A:$A,'Data(perSeason,perCrop)'!$S:$S,Indicators!$B18,'Data(perSeason,perCrop)'!$O:$O,Indicators!K$7,'Data(perSeason,perCrop)'!$C:$C,Indicators!K$3,'Data(perSeason,perCrop)'!$R:$R,"IRRIGATED") -> 67.455545 | L18: =SUMIFS('Data(perSeason,perCrop)'!$A:$A,'Data(perSeason,perCrop)'!$S:$S,Indicators!$B18,'Data(perSeason,perCrop)'!$O:$O,Indicators!L$7,'Data(perSeason,perCrop)'!$C:$C,Indicators!L$3,'Data(perSeason,perCrop)'!$R:$R,"IRRIGATED") -> 14.3836 | M18: =SUMIFS('Data(perSeason,perCrop)'!$A:$A,'Data(perSeason,perCrop)'!$S:$S,Indicators!$B18,'Data(perSeason,perCrop)'!$O:$O,Indicators!M$7,'Data(perSeason,perCrop)'!$C:$C,Indicators!M$3,'Data(perSeason,perCrop)'!$R:$R,"IRRIGATED") -> 11.209214 | N18: =SUMIFS('Data(perSeason,perCrop)'!$A:$A,'Data(perSeason,perCrop)'!$S:$S,Indicators!$B18,'Data(perSeason,perCrop)'!$O:$O,Indicators!N$7,'Data(perSeason,perCrop)'!$C:$C,Indicators!N$3,'Data(perSeason,perCrop)'!$R:$R,"IRRIGATED") -> 561.88327 | O18: =SUMIFS('Data(perSeason,perCrop)'!$A:$A,'Data(perSeason,perCrop)'!$S:$S,Indicators!$B18,'Data(perSeason,perCrop)'!$O:$O,Indicators!O$7,'Data(perSeason,perCrop)'!$C:$C,Indicators!O$3,'Data(perSeason,perCrop)'!$R:$R,"IRRIGATED") -> 4053.7929 | P18: =SUMIFS('Data(perSeason,perCrop)'!$A:$A,'Data(perSeason,perCrop)'!$S:$S,Indicators!$B18,'Data(perSeason,perCrop)'!$O:$O,Indicators!P$7,'Data(perSeason,perCrop)'!$C:$C,Indicators!P$3,'Data(perSeason,perCrop)'!$R:$R,"IRRIGATED") -> 33.569078 | Q18: =SUMIFS('Data(perSeason,perCrop)'!$A:$A,'Data(perSeason,perCrop)'!$S:$S,Indicators!$B18,'Data(perSeason,perCrop)'!$O:$O,Indicators!Q$7,'Data(perSeason,perCrop)'!$C:$C,Indicators!Q$3,'Data(perSeason,perCrop)'!$R:$R,"IRRIGATED") -> 2093.7228 | R18: =SUMIFS('Data(perSeason,perCrop)'!$A:$A,'Data(perSeason,perCrop)'!$S:$S,Indicators!$B18,'Data(perSeason,perCrop)'!$O:$O,Indicators!R$7,'Data(perSeason,perCrop)'!$C:$C,Indicators!R$3,'Data(perSeason,perCrop)'!$R:$R,"IRRIGATED") -> 0 | ... DG18: =SUMIFS('Data(perSeason,perCrop)'!$A:$A,'Data(perSeason,perCrop)'!$S:$S,Indicators!$B18,'Data(perSeason,perCrop)'!$O:$O,Indicators!DG$7,'Data(perSeason,perCrop)'!$C:$C,Indicators!DG$3,'Data(perSeason,perCrop)'!$R:$R,"IRRIGATED") -> 0
B19: 2022 | C19: =IF(COUNTIFS('Data(perSeason,perCrop)'!$S:$S,Indicators!$B19)>0,SUMIFS('Data(perSeason,perCrop)'!$A:$A,'Data(perSeason,perCrop)'!$S:$S,Indicators!$B19,'Data(perSeason,perCrop)'!$O:$O,Indicators!C$7,'Data(perSeason,perCrop)'!$R:$R,"IRRIGATED"),"") -> 5941.4719 | D19: =IF(COUNTIFS('Data(perSeason,perCrop)'!$S:$S,Indicators!$B19)>0,SUMIFS('Data(perSeason,perCrop)'!$A:$A,'Data(perSeason,perCrop)'!$S:$S,Indicators!$B19,'Data(perSeason,perCrop)'!$O:$O,Indicators!D$7,'Data(perSeason,perCrop)'!$R:$R,"IRRIGATED"),"") -> 7224.7289 | E19: =IF(COUNTIFS('Data(perSeason,perCrop)'!$S:$S,Indicators!$B19)>0,SUMIFS('Data(perSeason,perCrop)'!$A:$A,'Data(perSeason,perCrop)'!$S:$S,Indicators!$B19,'Data(perSeason,perCrop)'!$O:$O,Indicators!E$7,'Data(perSeason,perCrop)'!$R:$R,"IRRIGATED"),"") -> 4255.8917 | F19: =IF(COUNTIFS('Data(perSeason,perCrop)'!$S:$S,Indicators!$B19)>0,SUM(K19:R19),"") -> 9452.2954 | J19: ha | K19: =SUMIFS('Data(perSeason,perCrop)'!$A:$A,'Data(perSeason,perCrop)'!$S:$S,Indicators!$B19,'Data(perSeason,perCrop)'!$O:$O,Indicators!K$7,'Data(perSeason,perCrop)'!$C:$C,Indicators!K$3,'Data(perSeason,perCrop)'!$R:$R,"IRRIGATED") -> 0 | L19: =SUMIFS('Data(perSeason,perCrop)'!$A:$A,'Data(perSeason,perCrop)'!$S:$S,Indicators!$B19,'Data(perSeason,perCrop)'!$O:$O,Indicators!L$7,'Data(perSeason,perCrop)'!$C:$C,Indicators!L$3,'Data(perSeason,perCrop)'!$R:$R,"IRRIGATED") -> 0 | M19: =SUMIFS('Data(perSeason,perCrop)'!$A:$A,'Data(perSeason,perCrop)'!$S:$S,Indicators!$B19,'Data(perSeason,perCrop)'!$O:$O,Indicators!M$7,'Data(perSeason,perCrop)'!$C:$C,Indicators!M$3,'Data(perSeason,perCrop)'!$R:$R,"IRRIGATED") -> 0 | N19: =SUMIFS('Data(perSeason,perCrop)'!$A:$A,'Data(perSeason,perCrop)'!$S:$S,Indicators!$B19,'Data(perSeason,perCrop)'!$O:$O,Indicators!N$7,'Data(perSeason,perCrop)'!$C:$C,Indicators!N$3,'Data(perSeason,perCrop)'!$R:$R,"IRRIGATED") -> 597.41535 | O19: =SUMIFS('Data(perSeason,perCrop)'!$A:$A,'Data(perSeason,perCrop)'!$S:$S,Indicators!$B19,'Data(perSeason,perCrop)'!$O:$O,Indicators!O$7,'Data(perSeason,perCrop)'!$C:$C,Indicators!O$3,'Data(perSeason,perCrop)'!$R:$R,"IRRIGATED") -> 4785.7117 | P19: =SUMIFS('Data(perSeason,perCrop)'!$A:$A,'Data(perSeason,perCrop)'!$S:$S,Indicators!$B19,'Data(perSeason,perCrop)'!$O:$O,Indicators!P$7,'Data(perSeason,perCrop)'!$C:$C,Indicators!P$3,'Data(perSeason,perCrop)'!$R:$R,"IRRIGATED") -> 0 | Q19: =SUMIFS('Data(perSeason,perCrop)'!$A:$A,'Data(perSeason,perCrop)'!$S:$S,Indicators!$B19,'Data(perSeason,perCrop)'!$O:$O,Indicators!Q$7,'Data(perSeason,perCrop)'!$C:$C,Indicators!Q$3,'Data(perSeason,perCrop)'!$R:$R,"IRRIGATED") -> 4069.1684 | R19: =SUMIFS('Data(perSeason,perCrop)'!$A:$A,'Data(perSeason,perCrop)'!$S:$S,Indicators!$B19,'Data(perSeason,perCrop)'!$O:$O,Indicators!R$7,'Data(perSeason,perCrop)'!$C:$C,Indicators!R$3,'Data(perSeason,perCrop)'!$R:$R,"IRRIGATED") -> 0 | ... DG19: =SUMIFS('Data(perSeason,perCrop)'!$A:$A,'Data(perSeason,perCrop)'!$S:$S,Indicators!$B19,'Data(perSeason,perCrop)'!$O:$O,Indicators!DG$7,'Data(perSeason,perCrop)'!$C:$C,Indicators!DG$3,'Data(perSeason,perCrop)'!$R:$R,"IRRIGATED") -> 0
B20: AVERAGE | C20: =AVERAGE(C15:C19) -> 5711.8228 | D20: =AVERAGE(D15:D19) -> 6656.2862 | E20: =AVERAGE(E15:E19) -> 3740.0595 | F20: =AVERAGE(F15:F19) -> 8485.6459 | J20: ha | K20: =AVERAGE(K15:K19) -> 45.710786 | L20: =AVERAGE(L15:L19) -> 15.814908 | M20: =AVERAGE(M15:M19) -> 25.157964 | N20: =AVERAGE(N15:N19) -> 1024.1593 | O20: =AVERAGE(O15:O19) -> 4324.3526 | P20: =AVERAGE(P15:P19) -> 22.820754 | Q20: =AVERAGE(Q15:Q19) -> 3026.0516 | R20: =AVERAGE(R15:R19) -> 1.5778438 | ... DG20: =AVERAGE(DG15:DG19) -> 0
B21: min | C21: =(MIN(C15:C19)-AVERAGE(C15:C19))/AVERAGE(C15:C19) -> -0.31937771 | D21: =(MIN(D15:D19)-AVERAGE(D15:D19))/AVERAGE(D15:D19) -> -0.30968825 | E21: =(MIN(E15:E19)-AVERAGE(E15:E19))/AVERAGE(E15:E19) -> -0.40582891 | F21: =(MIN(F15:F19)-AVERAGE(F15:F19))/AVERAGE(F15:F19) -> -0.25886551 | K21: =K20/SUM($K20:$R20) -> 0.0053868364 | L21: =L20/SUM($K20:$R20) -> 0.0018637248 | M21: =M20/SUM($K20:$R20) -> 0.0029647672 | N21: =N20/SUM($K20:$R20) -> 0.12069315 | O21: =O20/SUM($K20:$R20) -> 0.50960796 | P21: =P20/SUM($K20:$R20) -> 0.0026893362 | Q21: =Q20/SUM($K20:$R20) -> 0.35660829 | R21: =R20/SUM($K20:$R20) -> 0.00018594269 | S21: =S20/SUM($S20:$AH20) -> 0 | T21: =T20/SUM($S20:$AH20) -> 0.89020582 | U21: =U20/SUM($S20:$AH20) -> 0 | V21: =V20/SUM($S20:$AH20) -> 0 | W21: =W20/SUM($S20:$AH20) -> 0 | X21: =X20/SUM($S20:$AH20) -> 0 | Y21: =Y20/SUM($S20:$AH20) -> 0 | Z21: =Z20/SUM($S20:$AH20) -> 0 | ... AW21: =AW20/SUM($S20:$AH20) -> 0 | AX21: =AX20/SUM($AY20:$BM20) -> 0 | AY21: =AY20/SUM($AY20:$BM20) -> 0.98589538 | AZ21: =AZ20/SUM($AY20:$BM20) -> 0 | BA21: =BA20/SUM($AY20:$BM20) -> 0 | BB21: =BB20/SUM($AY20:$BM20) -> 0 | BC21: =BC20/SUM($AY20:$BM20) -> 0 | BD21: =BD20/SUM($AY20:$BM20) -> 0 | BE21: =BE20/SUM($AY20:$BM20) -> 0 | ... CB21: =CB20/SUM($AY20:$BM20) -> 0 | CC21: =CC20/SUM($CD20:$CR20) -> 0 | CD21: =CD20/SUM($CD20:$CR20) -> 0 | CE21: =CE20/SUM($CD20:$CR20) -> 0 | CF21: =CF20/SUM($CD20:$CR20) -> 0 | CG21: =CG20/SUM($CD20:$CR20) -> 0 | CH21: =CH20/SUM($CD20:$CR20) -> 0 | CI21: =CI20/SUM($CD20:$CR20) -> 0 | CJ21: =CJ20/SUM($CD20:$CR20) -> 0 | ... DG21: =DG20/SUM($CD20:$CR20) -> 0
