Workbook

Sheet User_Inputs
B2: Name of scheme | C2: Ong | F2: Comments
B3: CCA (ha) | C3: 17276
B4: Total Command Area (ha) | C4: 30837.7
B5: Arable Land (ha) | C5: 16663
B6: Irrigable Land (ha) | C6: 13657
B7: Number of Years | C7: =COUNT(_xlfn.UNIQUE(#REF!)) -> 0 | F7: Consider years within the period 2018-2022 only
B9: Sheets | C9: Description | D9: Inputs Required | E9: Optional Inputs | F9: Comments
B10: SCORES | C10: Benchmarking: final values and scores | D10: Yes | E10: Yes
B11: Data(perSeason,perCrop) | C11: Data exported from GEE (per season, per crop, per year) | D11: Yes
B12: Data(perCrop) | C12: Data exported from GEE (per crop and per year) | D12: Yes
B13: Data(FAO-AQUASTAT) | C13: Crop water requirements according to FAO-AQUASTAT | D13: Yes | F13: Fraction of irrigated area currently represented: | G13: =#REF! -> #REF!
B14: Indicators | C14: Annual benchmarking indicators, overall
B15: Indicators(perCrop) | C15: Annual benchmarking indicators, per crop type
B16: SummaryTable | C16: Summary table of benchmarking statistics
B17: Figures | C17: Figures
B19: Indicator | C19: Description | D19: Unit | E19: Temporal Resolution | F19: Required Inputs | G19: Comment
A20: 1 | B20: Cropping Intensity | D20: - | E20: Annual | F20: "Data(perSeason,perCrop)": Area | G20: Calculate based on CCA
A21: 2 | B21: Irrigation Utilization | C21: Fraction of command area irrigated | D21: % | E21: Seasonal or Annual | F21: "Data(perSeason,perCrop)": Area | G21: Calculate based on CCA
A22: 3 | B22: Low Water Intensive Crops | C22: Fraction of low water intensive irrigated crops | D22: % | E22: Seasonal or Annual | F22: "Data(FAO-AQUASTAT)": ETc-Crop "Data(perCrop)": Area | G22: https://aquastat.fao.org/
A23: 4 | B23: Adequacy | C23: RWD=1-(Eta/Etp) | D23: - | E23: Seasonal or Annual | F23: "Data(perCrop)": Area, ETa, ETaMax
A24: 5 | B24: Equity | C24: Standard deviation of ETa over irrigated areas divided by average ETa | D24: - | E24: Seasonal or Annual | F24: "Data(perSeason,perCrop)": ETcv or Etcv_blue
A25: 6 | B25: Productivity | C25: Water Productivity (in terms of yield) | D25: kg/m3 | E25: Annual (per crop) | F25: "Data(perCrop)": TBP, ETa
A26: 7 | B26: Reliability | C26: Range of average crop-specific monthly Relative ET (ET/ETp), considering for each scheme the most common irrigated crop(s) and the corresponding cropping season | D26: % | E26: Annual (per crop) | F26: "Data(perSeason,perCrop)": RETmax, RETmin "Data(perCrop)": Area
A27: 8 | B27: Yield Gap due to water stress | C27: (Ypotential​−Yactual​​)/(Ypotential​)×100 | D27: % | E27: Annual (per crop) | F27: "Data(perCrop)": TBP, TBP_P

Sheet SCORES
B1: Indicator | C1: Description | D1: Units | E1: Crop Specific (Y/N) | F1: Crop Types | G1: Descending/Ascending | H1: Parameter | I1: Parameter value | J1: Critical Value | K1: Target Value | L1: Season (s) | P1: Indicator Weight | Q1: Value | R1: Score
L2: Kharif | M2: Rabi | N2: Zaid | O2: Annual
A3: 1 | B3: Cropping Intensity | C3: Cropping Intensity, considering CCA | D3: %/100 | E3: N | F3: All Annual Crops | G3: A | J3: 1 | K3: 1.5 | O3: 1 | P3: 1 | Q3: =#REF! -> #REF! | R3: =IF($G3="D",MIN(MAX(1,11-ROUND(((Q3-$K3)/($J3-$K3))*9+1,0)),10),MIN(MAX(1,ROUND(((Q3-$J3)/($K3-$J3))*9+1,0)),10)) -> #REF!
A4: 2 | B4: Irrigation Utilization | C4: Fraction of CCA irrigated | D4: %/100 | E4: N | F4: All Irrigated Crops | G4: A | J4: 0.25 | K4: 0.8 | O4: 1 | P4: 1 | Q4: =(L4*#REF!+SCORES!M4*#REF!+SCORES!N4*#REF!+SCORES!O4*#REF!)/SUM(L4:O4) -> #REF! | R4: =IF($G4="D",MIN(MAX(1,11-ROUND(((Q4-$K4)/($J4-$K4))*9+1,0)),10),MIN(MAX(1,ROUND(((Q4-$J4)/($K4-$J4))*9+1,0)),10)) -> #REF!
A5: 3 | B5: Low Water Intensive Crops | C5: Fraction of low water intensive irrigated crops, based on FAO-AQUASTAT crop water requirements | D5: %/100 | E5: Y | F5: All irrigated Crops, based on FAO-AQUASTAT crop water requirements | G5: A | H5: Threshold value to identify water intensive crops, per full cropping period [mm] | I5: 500 | J5: 0 | K5: 1 | O5: 1 | P5: 0 | Q5: =#REF! -> #REF! | R5: =IF($G5="D",MIN(MAX(1,11-ROUND(((IF(ISNUMBER(Q5),Q5,Q6)-$K5)/($J5-$K5))*9+1,0)),10),MIN(MAX(1,ROUND(((IF(ISNUMBER(Q5),Q5,Q6)-$J5)/($K5-$J5))*9+1,0)),10)) -> #REF!
E6: N | F6: All irrigated Crops, based on Etp (90th percentile of ETa according to RS analysis) | G6: A | H6: Threshold value to identify water intensive crops, per season [mm] | I6: 300 | J6: 0 | K6: 1 | L6: 1 | M6: 1 | O6: 1 | Q6: =(L6*#REF!+SCORES!M6*#REF!+SCORES!N6*#REF!+SCORES!O6*#REF!)/SUM(L6:O6) -> #REF!
A7: 4 | B7: Adequacy | C7: RWD=1-(Eta/Etp) | D7: - | E7: N | F7: Weighted mean of all crops (weighted by irrigated area per crop) | G7: D | J7: 0.4 | K7: 0 | O7: 1 | P7: 1 | Q7: =(L7*#REF!+SCORES!M7*#REF!+SCORES!N7*#REF!+SCORES!O7*#REF!)/SUM(L7:O7) -> #REF! | R7: =IF($G7="D",MIN(MAX(1,11-ROUND(((Q7-$K7)/($J7-$K7))*9+1,0)),10),MIN(MAX(1,ROUND(((Q7-$J7)/($K7-$J7))*9+1,0)),10)) -> #REF!
A8: 5 | B8: Equity | C8: Standard deviation of ETa over irrigated areas divided by average ETa | D8: - | E8: N | F8: Weighted mean of all crops (weighted by irrigated area per crop) | G8: D | J8: 0.4 | K8: 0 | M8: 1 | P8: 1 | Q8: =(L8*#REF!+SCORES!M8*#REF!+SCORES!N8*#REF!+SCORES!O8*#REF!)/SUM(L8:O8) -> #REF! | R8: =IF($G8="D",MIN(MAX(1,11-ROUND(((Q8-$K8)/($J8-$K8))*9+1,0)),10),MIN(MAX(1,ROUND(((Q8-$J8)/($K8-$J8))*9+1,0)),10)) -> #REF!
C9: Standard deviation of ETblue over irrigated areas divided by average ETblue | D9: - | E9: N | F9: Weighted mean of all crops (weighted by irrigated area per crop) | G9: D | K9: 0 | M9: 1 | P9: 0 | Q9: =(L9*#REF!+SCORES!M9*#REF!+SCORES!N9*#REF!+SCORES!O9*#REF!)/SUM(L9:O9) -> #REF! | R9: =IF(ISNUMBER(J9),IF($G9="D",MIN(MAX(1,11-ROUND(((Q9-$K9)/($J9-$K9))*9+1,0)),10),MIN(MAX(1,ROUND(((Q9-$J9)/($K9-$J9))*9+1,0)),10)),"")
A10: 6 | B10: Productivity | C10: Water Productivity (in terms of yield) | D10: kg/m3 | E10: Y | P10: 1 | R10: =AVERAGE(R11:R16) -> #DIV/0!
F11: Cotton | G11: A | J11: 0.10559418 | K11: 0.41678402 | Q11: =#REF! -> #REF! | R11: =IF(ISNUMBER(Q11),IF($G11="D",MIN(MAX(1,11-ROUND(((Q11-$K11)/($J11-$K11))*9+1,0)),10),MIN(MAX(1,ROUND(((Q11-$J11)/($K11-$J11))*9+1,0)),10)),"")
F12: Jowar | G12: A | J12: 0.53490679 | K12: 0.8184797 | Q12: =#REF! -> #REF! | R12: =IF(ISNUMBER(Q12),IF($G12="D",MIN(MAX(1,11-ROUND(((Q12-$K12)/($J12-$K12))*9+1,0)),10),MIN(MAX(1,ROUND(((Q12-$J12)/($K12-$J12))*9+1,0)),10)),"")
F13: Paddy | G13: A | J13: 0.46496334 | K13: 1 | Q13: =#REF! -> #REF! | R13: =IF(ISNUMBER(Q13),IF($G13="D",MIN(MAX(1,11-ROUND(((Q13-$K13)/($J13-$K13))*9+1,0)),10),MIN(MAX(1,ROUND(((Q13-$J13)/($K13-$J13))*9+1,0)),10)),"")
F14: Sugarcane | G14: A | J14: 3.8966165 | K14: 5.234192 | Q14: =#REF! -> #REF! | R14: =IF(ISNUMBER(Q14),IF($G14="D",MIN(MAX(1,11-ROUND(((Q14-$K14)/($J14-$K14))*9+1,0)),10),MIN(MAX(1,ROUND(((Q14-$J14)/($K14-$J14))*9+1,0)),10)),"")
F15: Mustard (Forage) | G15: A | J15: 2.9234075 | K15: 3.6598924 | Q15: =#REF! -> #REF! | R15: =IF(ISNUMBER(Q15),IF($G15="D",MIN(MAX(1,11-ROUND(((Q15-$K15)/($J15-$K15))*9+1,0)),10),MIN(MAX(1,ROUND(((Q15-$J15)/($K15-$J15))*9+1,0)),10)),"")
F16: Wheat | G16: A | J16: 1.0734831 | K16: 1.4866771 | Q16: =#REF! -> #REF! | R16: =IF(ISNUMBER(Q16),IF($G16="D",MIN(MAX(1,11-ROUND(((Q16-$K16)/($J16-$K16))*9+1,0)),10),MIN(MAX(1,ROUND(((Q16-$J16)/($K16-$J16))*9+1,0)),10)),"")
A17: 7 | B17: Reliability | C17: Range of average crop-specific monthly Relative ET (ET/ETp) | D17: %/100 | E17: N | F17: Weighted mean of all crops (weighted by irrigated area per crop) | G17: D | J17: 0.4 | K17: 0 | P17: 1 | Q17: =#REF! -> #REF! | R17: =IF($G17="D",MIN(MAX(1,11-ROUND(((Q17-$K17)/($J17-$K17))*9+1,0)),10),MIN(MAX(1,ROUND(((Q17-$J17)/($K17-$J17))*9+1,0)),10)) -> #REF!
A18: 8 | B18: Yield Gap due to water stress | C18: (Ypotential​−Yactual​​)/(Ypotential​)×100 | D18: %/100 | E18: N | F18: Weighted mean of all crops (weighted by irrigated area per crop) | G18: D | J18: 0.4 | K18: 0 | P18: 1 | Q18: =#REF! -> #REF! | R18: =IF($G18="D",MIN(MAX(1,11-ROUND(((Q18-$K18)/($J18-$K18))*9+1,0)),10),MIN(MAX(1,ROUND(((Q18-$J18)/($K18-$J18))*9+1,0)),10)) -> #REF!
Q20: AVERAGE SCORE | R20: =(SUMPRODUCT($P7:$P10,R7:R10)+SUMPRODUCT($P17:$P18,R17:R18)+SUMPRODUCT($P3:$P5,R3:R5))/SUM($P7:$P10,$P17:$P18,P3:P5) -> #REF!

Sheet SummaryTable
A1: =SCORES!B1 -> Indicator | B1: =SCORES!C1 -> Description | C1: =SCORES!D1 -> Units | D1: =SCORES!J1 -> Critical Value | E1: =SCORES!K1 -> Target Value | F1: =SCORES!Q1 -> Value | G1: Score
A2: =SCORES!B3 -> Cropping Intensity | B2: =SCORES!C3 -> Cropping Intensity, considering CCA | C2: =SCORES!D3 -> %/100 | D2: =SCORES!J3 -> 1 | E2: =SCORES!K3 -> 1.5 | F2: =SCORES!Q3 -> #REF! | G2: =SCORES!R3 -> #REF!
A3: =SCORES!B4 -> Irrigation Utilization | B3: =SCORES!C4 -> Fraction of CCA irrigated | C3: =SCORES!D4 -> %/100 | D3: =SCORES!J4 -> 0.25 | E3: =SCORES!K4 -> 0.8 | F3: =SCORES!Q4 -> #REF! | G3: =SCORES!R4 -> #REF!
A4: =SCORES!B5 -> Low Water Intensive Crops | B4: Fraction of low water intensive irrigated crops | C4: =SCORES!D5 -> %/100 | D4: =SCORES!J5 -> 0 | E4: =SCORES!K5 -> 1 | F4: =IF(ISNUMBER(SCORES!Q5),SCORES!Q5,SCORES!Q6) -> #REF! | G4: =SCORES!R5 -> #REF!
A5: =SCORES!B7 -> Adequacy | B5: =SCORES!C7 -> RWD=1-(Eta/Etp) | C5: =SCORES!D7 -> - | D5: =SCORES!J7 -> 0.4 | E5: =SCORES!K7 -> 0 | F5: =SCORES!Q7 -> #REF! | G5: =SCORES!R7 -> #REF!
A6: =SCORES!B8 -> Equity | B6: =SCORES!C8 -> Standard deviation of ETa over irrigated areas divided by average ETa | C6: =SCORES!D8 -> - | D6: =SCORES!J8 -> 0.4 | E6: =SCORES!K8 -> 0 | F6: =SCORES!Q8 -> #REF! | G6: =SCORES!R8 -> #REF!
A7: =SCORES!B10 -> Productivity | B7: =SCORES!C10 -> Water Productivity (in terms of yield) | C7: =SCORES!D10 -> kg/m3 | G7: =SCORES!R10 -> #DIV/0!
B8: Cotton | D8: 0.10559418 | E8: 0.41678402 | F8: =SCORES!Q11 -> #REF! | G8: =SCORES!R11
B9: Jowar | D9: 0.53490679 | E9: 0.8184797 | F9: =SCORES!Q12 -> #REF! | G9: =SCORES!R12
B10: Paddy | D10: 0.46496334 | E10: 1 | F10: =SCORES!Q13 -> #REF! | G10: =SCORES!R13
B11: Sugarcane | D11: 3.8966165 | E11: 5.234192 | F11: =SCORES!Q14 -> #REF! | G11: =SCORES!R14
B12: Mustard (Forage) | D12: 2.9234075 | E12: 3.6598924 | F12: =SCORES!Q15 -> #REF! | G12: =SCORES!R15
B13: Wheat | D13: 1.0734831 | E13: 1.4866771 | F13: =SCORES!Q16 -> #REF! | G13: =SCORES!R16
A14: =SCORES!B17 -> Reliability | B14: =SCORES!C17 -> Range of average crop-specific monthly Relative ET (ET/ETp) | C14: =SCORES!D17 -> %/100 | D14: =SCORES!J17 -> 0.4 | E14: =SCORES!K17 -> 0 | F14: =SCORES!Q17 -> #REF! | G14: =SCORES!R17 -> #REF!
A15: =SCORES!B18 -> Yield Gap due to water stress | B15: =SCORES!C18 -> (Ypotential​−Yactual​​)/(Ypotential​)×100 | C15: =SCORES!D18 -> %/100 | D15: =SCORES!J18 -> 0.4 | E15: =SCORES!K18 -> 0 | F15: =SCORES!Q18 -> #REF! | G15: =SCORES!R18 -> #REF!
F16: =SCORES!Q20 -> AVERAGE SCORE | G16: =AVERAGE(G14:G15,G2:G7) -> #REF!

Sheet Data(perSeason,perCrop)
A1: Area | B1: Area% | C1: Crop Type | D1: CropID | E1: ETa | F1: ETa90 | G1: ETblue | H1: ETcv | I1: ETcv_blue | J1: ETgreen | K1: Name | L1: Precip | M1: RETmax | N1: RETmin | O1: Season | P1: TBP | Q1: TBP_P | R1: status | S1: year | T1: Water Intensive (based on Etp)
A2: 892.75171 | B2: 7.6 | C2: Class1 | D2: 31 | E2: 287 | F2: 344 | G2: 68 | H2: 0.12617248 | I2: 0.52725009 | J2: 217 | K2: Ong | L2: 1313 | M2: 0.90091946 | N2: 0.42328921 | O2: 1 | P2: 6243 | Q2: 7324 | R2: IRRIGATED | S2: 2018 | T2: =IF(R2="IRRIGATED",IF(F2>=SCORES!I$6,1,0),"") -> 1
A3: 493.76833 | B3: 4.7 | C3: Class1 | D3: 31 | E3: 222 | F3: 262 | G3: 23 | H3: 0.040802421 | I3: 0.38562956 | J3: 194 | K3: Ong | L3: 52 | M3: 0.91055893 | N3: 0.90898866 | O3: 2 | P3: 5782 | Q3: 8449 | R3: IRRIGATED | S3: 2018 | T3: =IF(R3="IRRIGATED",IF(F3>=SCORES!I$6,1,0),"") -> 0
A4: 32.092348 | B4: 1.2 | C4: Class1 | D4: 31 | E4: 389 | F4: 493 | G4: 109 | H4: 0.098095935 | I4: 0.33488716 | J4: 278 | K4: Ong | L4: 85 | O4: 3 | P4: 2846 | Q4: 3909 | R4: IRRIGATED | S4: 2018 | T4: =IF(R4="IRRIGATED",IF(F4>=SCORES!I$6,1,0),"") -> 1
A5: 490.68953 | B5: 4.2 | C5: Class1 | D5: 31 | E5: 217 | F5: 246 | G5: 0 | J5: 215 | K5: Ong | L5: 1255 | M5: 0.90091946 | N5: 0.42328921 | O5: 1 | P5: 5039 | R5: RAINFED | S5: 2018 | T5: =IF(R5="IRRIGATED",IF(F5>=SCORES!I$6,1,0),"")
A6: 524.99812 | B6: 5 | C6: Class1 | D6: 31 | E6: 195 | F6: 206 | G6: 0 | J6: 190 | K6: Ong | L6: 51 | M6: 0.91055893 | N6: 0.90898866 | O6: 2 | P6: 4683 | R6: RAINFED | S6: 2018 | T6: =IF(R6="IRRIGATED",IF(F6>=SCORES!I$6,1,0),"")
A7: 4.0898163 | B7: 0.2 | C7: Class1 | D7: 31 | E7: 239 | F7: 456 | G7: 0 | J7: 189 | K7: Ong | L7: 56 | O7: 3 | P7: 1963 | R7: RAINFED | S7: 2018 | T7: =IF(R7="IRRIGATED",IF(F7>=SCORES!I$6,1,0),"")
A8: 1103.4964 | B8: 9.4 | C8: Class4 | D8: 34 | E8: 302 | F8: 358 | G8: 82 | H8: 0.12617248 | I8: 0.52725009 | J8: 218 | K8: Ong | L8: 1342 | M8: 0.92854274 | N8: 0.49314123 | O8: 1 | P8: 6380 | Q8: 7342 | R8: IRRIGATED | S8: 2018 | T8: =IF(R8="IRRIGATED",IF(F8>=SCORES!I$6,1,0),"") -> 1
A9: 1027.5863 | B9: 9.9 | C9: Class4 | D9: 34 | E9: 263 | F9: 336 | G9: 34 | H9: 0.040802421 | I9: 0.38562956 | J9: 224 | K9: Ong | L9: 57 | M9: 0.92393575 | N9: 0.90944058 | O9: 2 | P9: 7535 | Q9: 10404 | R9: IRRIGATED | S9: 2018 | T9: =IF(R9="IRRIGATED",IF(F9>=SCORES!I$6,1,0),"") -> 1
A10: 788.22197 | B10: 29.9 | C10: Class4 | D10: 34 | E10: 460 | F10: 553 | G10: 151 | H10: 0.098095935 | I10: 0.33488716 | J10: 307 | K10: Ong | L10: 99 | O10: 3 | P10: 3435 | Q10: 4487 | R10: IRRIGATED | S10: 2018 | T10: =IF(R10="IRRIGATED",IF(F10>=SCORES!I$6,1,0),"") -> 1
A11: 327.26934 | B11: 2.8 | C11: Class4 | D11: 34 | E11: 225 | F11: 302 | G11: 0 | J11: 217 | K11: Ong | L11: 1303 | M11: 0.92854274 | N11: 0.49314123 | O11: 1 | P11: 5071 | R11: RAINFED | S11: 2018 | T11: =IF(R11="IRRIGATED",IF(F11>=SCORES!I$6,1,0),"")
A12: 368.60111 | B12: 3.5 | C12: Class4 | D12: 34 | E12: 238 | F12: 320 | G12: 0 | J12: 224 | K12: Ong | L12: 57 | M12: 0.92393575 | N12: 0.90944058 | O12: 2 | P12: 6439 | R12: RAINFED | S12: 2018 | T12: =IF(R12="IRRIGATED",IF(F12>=SCORES!I$6,1,0),"")
A13: 55.825652 | B13: 2.1 | C13: Class4 | D13: 34 | E13: 407 | F13: 529 | G13: 0 | J13: 291 | K13: Ong | L13: 95 | O13: 3 | P13: 3451 | R13: RAINFED | S13: 2018 | T13: =IF(R13="IRRIGATED",IF(F13>=SCORES!I$6,1,0),"")
A14: 59.843344 | B14: 0.5 | C14: Double Crop Kharif/Rabi | D14: 4 | E14: 633 | F14: 745 | G14: 88 | H14: 0.089735728 | I14: 0.75002359 | J14: 523 | K14: Ong | L14: 1242 | O14: 0 | P14: 15645 | Q14: 18670 | R14: IRRIGATED | S14: 2018 | T14: =IF(R14="IRRIGATED",IF(F14>=SCORES!I$6,1,0),"") -> 1
A15: 10.83453 | B15: 0.1 | C15: Double Crop Kharif/Rabi | D15: 4 | E15: 418 | F15: 569 | G15: 0 | J15: 394 | K15: Ong | L15: 1184 | O15: 0 | P15: 9845 | R15: RAINFED | S15: 2018 | T15: =IF(R15="IRRIGATED",IF(F15>=SCORES!I$6,1,0),"")
A16: 2204.0052 | B16: 18.7 | C16: Double Crop Kharif/Zaid | D16: 5 | E16: 954 | F16: 1107 | G16: 248 | H16: 0.089735728 | I16: 0.75002359 | J16: 700 | K16: Ong | L16: 1401 | O16: 0 | P16: 14847 | Q16: 17291 | R16: IRRIGATED | S16: 2018 | T16: =IF(R16="IRRIGATED",IF(F16>=SCORES!I$6,1,0),"") -> 1
A17: 44.942276 | B17: 0.4 | C17: Double Crop Kharif/Zaid | D17: 5 | E17: 733 | F17: 1003 | G17: 0 | J17: 632 | K17: Ong | L17: 1363 | O17: 0 | P17: 11556 | R17: RAINFED | S17: 2018 | T17: =IF(R17="IRRIGATED",IF(F17>=SCORES!I$6,1,0),"")
A18: 6429.0186 | B18: 54.5 | C18: Kharif Crop | D18: 1 | E18: 496 | F18: 573 | G18: 81 | H18: 0.089735728 | I18: 0.75002359 | J18: 406 | K18: Ong | L18: 1313 | O18: 0 | P18: 11892 | Q18: 14094 | R18: IRRIGATED | S18: 2018 | T18: =IF(R18="IRRIGATED",IF(F18>=SCORES!I$6,1,0),"") -> 1
A19: 2248.5741 | B19: 19.1 | C19: Kharif Crop | D19: 1 | E19: 388 | F19: 469 | G19: 0 | J19: 377 | K19: Ong | L19: 1301 | O19: 0 | P19: 8815 | R19: RAINFED | S19: 2018 | T19: =IF(R19="IRRIGATED",IF(F19>=SCORES!I$6,1,0),"")
A20: 1486.8461 | B20: 56.5 | C20: Other Irrigated (High Water Intensive) | D20: 14 | E20: 493 | F20: 573 | G20: 181 | H20: 0.098095935 | I20: 0.33488716 | J20: 310 | K20: Ong | L20: 99 | O20: 3 | P20: 3385 | Q20: 4074 | R20: IRRIGATED | S20: 2018 | T20: =IF(R20="IRRIGATED",IF(F20>=SCORES!I$6,1,0),"") -> 1
A21: 141.06024 | B21: 1.2 | C21: Other Irrigated (High Water Intensive) | D21: 14 | E21: 342 | F21: 378 | G21: 125 | H21: 0.12617248 | I21: 0.52725009 | J21: 216 | K21: Ong | L21: 1345 | O21: 1 | P21: 6652 | Q21: 7128 | R21: IRRIGATED | S21: 2018 | T21: =IF(R21="IRRIGATED",IF(F21>=SCORES!I$6,1,0),"") -> 1
A22: 13.135225 | B22: 0.1 | C22: Other Irrigated (High Water Intensive) | D22: 14 | E22: 340 | F22: 388 | G22: 0 | J22: 210 | K22: Ong | L22: 1296 | O22: 1 | P22: 6662 | R22: RAINFED | S22: 2018 | T22: =IF(R22="IRRIGATED",IF(F22>=SCORES!I$6,1,0),"")
A23: 23.214123 | B23: 0.9 | C23: Other Irrigated (High Water Intensive) | D23: 14 | E23: 290 | F23: 577 | G23: 0 | J23: 182 | K23: Ong | L23: 59 | O23: 3 | P23: 2281 | R23: RAINFED | S23: 2018 | T23: =IF(R23="IRRIGATED",IF(F23>=SCORES!I$6,1,0),"")
A24: 180.69504 | B24: 6.9 | C24: Other Irrigated (Less Water Intensive) | D24: 15 | E24: 336 | F24: 412 | G24: 76 | H24: 0.098095935 | I24: 0.33488716 | J24: 258 | K24: Ong | L24: 68 | O24: 3 | P24: 2729 | Q24: 3429 | R24: IRRIGATED | S24: 2018 | T24: =IF(R24="IRRIGATED",IF(F24>=SCORES!I$6,1,0),"") -> 1
A25: 501.66726 | B25: 4.3 | C25: Other Irrigated (Less Water Intensive) | D25: 15 | E25: 288 | F25: 314 | G25: 71 | H25: 0.12617248 | I25: 0.52725009 | J25: 216 | K25: Ong | L25: 1300 | O25: 1 | P25: 6208 | Q25: 6619 | R25: IRRIGATED | S25: 2018 | T25: =IF(R25="IRRIGATED",IF(F25>=SCORES!I$6,1,0),"") -> 1
A26: 54.598896 | B26: 0.5 | C26: Other Irrigated (Less Water Intensive) | D26: 15 | E26: 229 | F26: 288 | G26: 28 | H26: 0.040802421 | I26: 0.38562956 | J26: 197 | K26: Ong | L26: 52 | O26: 2 | P26: 6293 | Q26: 9319 | R26: IRRIGATED | S26: 2018 | T26: =IF(R26="IRRIGATED",IF(F26>=SCORES!I$6,1,0),"") -> 0
A27: 54.429869 | B27: 0.5 | C27: Other Irrigated (Less Water Intensive) | D27: 15 | E27: 266 | F27: 308 | G27: 0 | J27: 209 | K27: Ong | L27: 1264 | O27: 1 | P27: 5810 | R27: RAINFED | S27: 2018 | T27: =IF(R27="IRRIGATED",IF(F27>=SCORES!I$6,1,0),"")
A28: 33.877615 | B28: 0.3 | C28: Other Irrigated (Less Water Intensive) | D28: 15 | E28: 260 | F28: 344 | G28: 0 | J28: 222 | K28: Ong | L28: 57 | O28: 2 | P28: 7359 | R28: RAINFED | S28: 2018 | T28: =IF(R28="IRRIGATED",IF(F28>=SCORES!I$6,1,0),"")
A29: 7.8548074 | B29: 0.3 | C29: Other Irrigated (Less Water Intensive) | D29: 15 | E29: 147 | F29: 370 | G29: 0 | J29: 118 | K29: Ong | L29: 32 | O29: 3 | P29: 1338 | R29: RAINFED | S29: 2018 | T29: =IF(R29="IRRIGATED",IF(F29>=SCORES!I$6,1,0),"")
A30: 1586.7494 | B30: 13.5 | C30: Other Unirrigated | D30: 17 | E30: 221 | F30: 264 | G30: 0 | J30: 213 | K30: Ong | L30: 1247 | O30: 1 | P30: 4919 | R30: RAINFED | S30: 2018 | T30: =IF(R30="IRRIGATED",IF(F30>=SCORES!I$6,1,0),"")
A31: 1321.155 | B31: 12.7 | C31: Other Unirrigated | D31: 17 | E31: 193 | F31: 212 | G31: 0 | J31: 186 | K31: Ong | L31: 50 | O31: 2 | P31: 4657 | R31: RAINFED | S31: 2018 | T31: =IF(R31="IRRIGATED",IF(F31>=SCORES!I$6,1,0),"")
A32: 53.557748 | B32: 2 | C32: Other Unirrigated | D32: 17 | E32: 258 | F32: 329 | G32: 0 | J32: 219 | K32: Ong | L32: 50 | O32: 3 | P32: 2748 | R32: RAINFED | S32: 2018 | T32: =IF(R32="IRRIGATED",IF(F32>=SCORES!I$6,1,0),"")
A33: 5050.8789 | B33: 43 | C33: Paddy | D33: 2 | E33: 289 | F33: 346 | G33: 71 | H33: 0.12617248 | I33: 0.52725009 | J33: 216 | K33: Ong | L33: 1265 | M33: 0.95435268 | N33: 0.41419999 | O33: 1 | P33: 6299 | Q33: 7355 | R33: IRRIGATED | S33: 2018 | T33: =IF(R33="IRRIGATED",IF(F33>=SCORES!I$6,1,0),"") -> 1
A34: 5992.4791 | B34: 57.5 | C34: Paddy | D34: 2 | E34: 228 | F34: 272 | G34: 32 | H34: 0.040802421 | I34: 0.38562956 | J34: 194 | K34: Ong | L34: 51 | M34: 0.95441365 | N34: 0.91788744 | O34: 2 | P34: 6299 | Q34: 8955 | R34: IRRIGATED | S34: 2018 | T34: =IF(R34="IRRIGATED",IF(F34>=SCORES!I$6,1,0),"") -> 0
A35: 1596.0866 | B35: 13.6 | C35: Paddy | D35: 2 | E35: 212 | F35: 244 | G35: 0 | J35: 211 | K35: Ong | L35: 1158 | M35: 0.95435268 | N35: 0.41419999 | O35: 1 | P35: 4793 | R35: RAINFED | S35: 2018 | T35: =IF(R35="IRRIGATED",IF(F35>=SCORES!I$6,1,0),"")
A36: 611.32789 | B36: 5.9 | C36: Paddy | D36: 2 | E36: 202 | F36: 220 | G36: 0 | J36: 192 | K36: Ong | L36: 51 | M36: 0.95441365 | N36: 0.91788744 | O36: 2 | P36: 5126 | R36: RAINFED | S36: 2018 | T36: =IF(R36="IRRIGATED",IF(F36>=SCORES!I$6,1,0),"")
A37: 674.8299 | B37: 5.7 | C37: Perennial Crops | D37: 8 | E37: 1041 | F37: 1197 | G37: 224 | H37: 0.089735728 | I37: 0.75002359 | J37: 800 | K37: Ong | L37: 1503 | O37: 0 | P37: 19377 | Q37: 21259 | R37: IRRIGATED | S37: 2018 | T37: =IF(R37="IRRIGATED",IF(F37>=SCORES!I$6,1,0),"") -> 1
A38: 122.03933 | B38: 1 | C38: Perennial Crops | D38: 8 | E38: 1012 | F38: 1185 | G38: 0 | J38: 806 | K38: Ong | L38: 1513 | O38: 0 | P38: 19070 | R38: RAINFED | S38: 2018 | T38: =IF(R38="IRRIGATED",IF(F38>=SCORES!I$6,1,0),"")
A39: 486.04367 | B39: 3.8 | C39: Class1 | D39: 31 | E39: 223 | F39: 320 | G39: 22 | H39: 0.042562362 | I39: 0.54302631 | J39: 195 | K39: Ong | L39: 93 | M39: 0.9251526 | N39: 0.90250255 | O39: 2 | P39: 6349 | Q39: 9465 | R39: IRRIGATED | S39: 2019 | T39: =IF(R39="IRRIGATED",IF(F39>=SCORES!I$6,1,0),"") -> 1
A40: 804.6482 | B40: 6 | C40: Class1 | D40: 31 | E40: 235 | F40: 296 | G40: 45 | H40: 0.19330612 | I40: 0.89136115 | J40: 187 | K40: Ong | L40: 1172 | M40: 0.91927536 | N40: 0.35232797 | O40: 1 | P40: 4175 | Q40: 5169 | R40: IRRIGATED | S40: 2019 | T40: =IF(R40="IRRIGATED",IF(F40>=SCORES!I$6,1,0),"") -> 0
...

Sheet Data(perCrop)
A1: Area | B1: Crop Type | C1: CropID | D1: ETa | E1: ETaMax | F1: ETblue | G1: ETgreen | H1: Name | I1: Precip | J1: Season | K1: TBP | L1: TBP_P | M1: cropping_intensity | N1: status | O1: year | P1: Water Intensive (based on Etp) | Q1: Etblue Vol
A2: 1017.1803 | B2: Class1 | C2: 31 | D2: 507 | E2: 603 | F2: 78 | G2: 420 | H2: Ong | I2: 1362 | J2: 4 | K2: 11292 | L2: 14944 | M2: 1 | N2: IRRIGATED | O2: 2018 | P2: =IF(N2="IRRIGATED",IF(E2/M2>=[1]SCORES!I$5,1,0),"") -> 1 | Q2: =A2*10000*F2/1000/10^6 -> 0.7934006 | S2: =(K2-L2)/L2 -> -0.24437901
A3: 1019.7181 | B3: Class1 | C3: 31 | D3: 535 | E3: 875 | F3: 71 | G3: 452 | H3: Ong | I3: 1281 | J3: 4 | K3: 10837 | L3: 18161 | M3: 1 | N3: IRRIGATED | O3: 2019 | P3: =IF(N3="IRRIGATED",IF(E3/M3>=[1]SCORES!I$5,1,0),"") -> 1 | Q3: =A3*10000*F3/1000/10^6 -> 0.72399983 | S3: =(K3-L3)/L3 -> -0.40328176
A4: 783.95728 | B4: Class1 | C4: 31 | D4: 562 | E4: 763 | F4: 90 | G4: 469 | H4: Ong | I4: 1518 | J4: 4 | K4: 9865 | L4: 13502 | M4: 1 | N4: IRRIGATED | O4: 2020 | P4: =IF(N4="IRRIGATED",IF(E4/M4>=[1]SCORES!I$5,1,0),"") -> 1 | Q4: =A4*10000*F4/1000/10^6 -> 0.70556155 | S4: =(K4-L4)/L4 -> -0.2693675
A5: 970.67386 | B5: Class1 | C5: 31 | D5: 461 | E5: 675 | F5: 66 | G5: 388 | H5: Ong | I5: 975 | J5: 4 | K5: 9157 | L5: 13912 | M5: 1 | N5: IRRIGATED | O5: 2021 | P5: =IF(N5="IRRIGATED",IF(E5/M5>=[1]SCORES!I$5,1,0),"") -> 1 | Q5: =A5*10000*F5/1000/10^6 -> 0.64064475 | S5: =(K5-L5)/L5 -> -0.34179126
A6: 754.58174 | B6: Class1 | C6: 31 | D6: 546 | E6: 811 | F6: 73 | G6: 462 | H6: Ong | I6: 1347 | J6: 4 | K6: 11009 | L6: 15429 | M6: 1 | N6: IRRIGATED | O6: 2022 | P6: =IF(N6="IRRIGATED",IF(E6/M6>=[1]SCORES!I$5,1,0),"") -> 1 | Q6: =A6*10000*F6/1000/10^6 -> 0.55084467 | S6: =(K6-L6)/L6 -> -0.28647352
A7: 1372.5328 | B7: Class4 | C7: 34 | D7: 859 | E7: 1147 | F7: 195 | G7: 653 | H7: Ong | I7: 1460 | J7: 4 | K7: 15669 | L7: 20782 | M7: 2 | N7: IRRIGATED | O7: 2018 | P7: =IF(N7="IRRIGATED",IF(E7/M7>=[1]SCORES!I$5,1,0),"") -> 1 | Q7: =A7*10000*F7/1000/10^6 -> 2.676439 | S7: =(K7-L7)/L7 -> -0.24603022
A8: 5645.1071 | B8: Class4 | C8: 34 | D8: 839 | E8: 1059 | F8: 158 | G8: 670 | H8: Ong | I8: 1429 | J8: 4 | K8: 15935 | L8: 20708 | M8: 4 | N8: IRRIGATED | O8: 2019 | P8: =IF(N8="IRRIGATED",IF(E8/M8>=[1]SCORES!I$5,1,0),"") -> 0 | Q8: =A8*10000*F8/1000/10^6 -> 8.9192692 | S8: =(K8-L8)/L8 -> -0.23049063
A9: 539.54579 | B9: Class4 | C9: 34 | D9: 888 | E9: 1131 | F9: 215 | G9: 668 | H9: Ong | I9: 1676 | J9: 4 | K9: 13516 | L9: 18185 | M9: 2 | N9: IRRIGATED | O9: 2020 | P9: =IF(N9="IRRIGATED",IF(E9/M9>=[1]SCORES!I$5,1,0),"") -> 1 | Q9: =A9*10000*F9/1000/10^6 -> 1.1600235 | S9: =(K9-L9)/L9 -> -0.25675007
A10: 866.44823 | B10: Class4 | C10: 34 | D10: 871 | E10: 1083 | F10: 260 | G10: 597 | H10: Ong | I10: 1242 | J10: 4 | K10: 12914 | L10: 17184 | M10: 2 | N10: IRRIGATED | O10: 2021 | P10: =IF(N10="IRRIGATED",IF(E10/M10>=[1]SCORES!I$5,1,0),"") -> 1 | Q10: =A10*10000*F10/1000/10^6 -> 2.2527654 | S10: =(K10-L10)/L10 -> -0.24848696
A11: 1736.8013 | B11: Class4 | C11: 34 | D11: 854 | E11: 1099 | F11: 192 | G11: 651 | H11: Ong | I11: 1404 | J11: 4 | K11: 14967 | L11: 19437 | M11: 2 | N11: IRRIGATED | O11: 2022 | P11: =IF(N11="IRRIGATED",IF(E11/M11>=[1]SCORES!I$5,1,0),"") -> 1 | Q11: =A11*10000*F11/1000/10^6 -> 3.3346585 | S11: =(K11-L11)/L11 -> -0.22997376
A12: 1618.8685 | B12: Other Irrigated (High Water Intensive) | C12: 14 | D12: 482 | E12: 571 | F12: 177 | G12: 304 | H12: Ong | I12: 208 | J12: 4 | K12: 3689 | L12: 4362 | M12: 2 | N12: IRRIGATED | O12: 2018 | P12: =IF(N12="IRRIGATED",IF(E12/M12>=[1]SCORES!I$5,1,0),"") -> 0 | Q12: =A12*10000*F12/1000/10^6 -> 2.8653972 | S12: =(K12-L12)/L12 -> -0.15428702
A13: 1953.9863 | B13: Other Irrigated (High Water Intensive) | C13: 14 | D13: 477 | E13: 537 | F13: 169 | G13: 306 | H13: Ong | I13: 173 | J13: 4 | K13: 5521 | L13: 6267 | M13: 2 | N13: IRRIGATED | O13: 2019 | P13: =IF(N13="IRRIGATED",IF(E13/M13>=[1]SCORES!I$5,1,0),"") -> 0 | Q13: =A13*10000*F13/1000/10^6 -> 3.3022368 | S13: =(K13-L13)/L13 -> -0.11903622
... A26: 6400.6442 | B26: Paddy | C26: 2 | D26: 445 | E26: 521 | F26: 49 | G26: 392 | H26: Ong | I26: 1164 | J26: 4 | K26: 10421 | L26: 12988 | M26: 1 | N26: IRRIGATED | O26: 2022 | P26: =IF(N26="IRRIGATED",IF(E26/M26>=[1]SCORES!I$5,1,0),"") -> 1 | Q26: =A26*10000*F26/1000/10^6 -> 3.1363157 | S26: =(K26-L26)/L26 -> -0.19764398
P51: =IF(N51="IRRIGATED",IF(E51/M51>=[1]SCORES!I$5,1,0),"") | Q51: =A51*10000*F51/1000/10^6 -> 0
P52: =IF(N52="IRRIGATED",IF(E52/M52>=[1]SCORES!I$5,1,0),"") | Q52: =A52*10000*F52/1000/10^6 -> 0
P53: =IF(N53="IRRIGATED",IF(E53/M53>=[1]SCORES!I$5,1,0),"") | Q53: =A53*10000*F53/1000/10^6 -> 0
P54: =IF(N54="IRRIGATED",IF(E54/M54>=[1]SCORES!I$5,1,0),"") | Q54: =A54*10000*F54/1000/10^6 -> 0
P55: =IF(N55="IRRIGATED",IF(E55/M55>=[1]SCORES!I$5,1,0),"") | Q55: =A55*10000*F55/1000/10^6 -> 0
P56: =IF(N56="IRRIGATED",IF(E56/M56>=[1]SCORES!I$5,1,0),"") | Q56: =A56*10000*F56/1000/10^6 -> 0
P57: =IF(N57="IRRIGATED",IF(E57/M57>=[1]SCORES!I$5,1,0),"") | Q57: =A57*10000*F57/1000/10^6 -> 0
P58: =IF(N58="IRRIGATED",IF(E58/M58>=[1]SCORES!I$5,1,0),"") | Q58: =A58*10000*F58/1000/10^6 -> 0
P59: =IF(N59="IRRIGATED",IF(E59/M59>=[1]SCORES!I$5,1,0),"") | Q59: =A59*10000*F59/1000/10^6 -> 0
P60: =IF(N60="IRRIGATED",IF(E60/M60>=[1]SCORES!I$5,1,0),"") | Q60: =A60*10000*F60/1000/10^6 -> 0
P61: =IF(N61="IRRIGATED",IF(E61/M61>=[1]SCORES!I$5,1,0),"") | Q61: =A61*10000*F61/1000/10^6 -> 0
P62: =IF(N62="IRRIGATED",IF(E62/M62>=[1]SCORES!I$5,1,0),"") | Q62: =A62*10000*F62/1000/10^6 -> 0
... P142: =IF(N142="IRRIGATED",IF(E142/M142>=[1]SCORES!I$5,1,0),"") | Q142: =A142*10000*F142/1000/10^6 -> 0

Sheet Cropping_Intensity
A2: CCA | B2: 17276 | D2: User Specified
B4: Double Crop Kharif/Rabi | C4: Double Crop Rabi/Zaid | D4: Triple Crop | E4: Perennial Crops | F4: Kharif Crop | G4: Rabi Crop | H4: Double Crop Kharif/Zaid | I4: Zaid Crop
A5: ID | B5: 1 | C5: 2 | D5: 3 | E5: 4 | F5: 5 | G5: 6 | H5: 7 | I5: 8
A6: Cropping Intensity | B6: 2 | C6: 2 | D6: 3 | E6: 1 | F6: 1 | G6: 1 | H6: 2 | I6: 1
A7: Season (Annual) | B7: 0 | C7: 0 | D7: 0 | E7: 0 | F7: 0 | G7: 0 | H7: 0 | I7: 0
A9: Cropped Area | B9: Double Crop Kharif/Rabi | C9: Double Crop Rabi/Zaid | D9: Triple Crop | E9: Perennial Crops | F9: Kharif Crop | G9: Rabi Crop | H9: Double Crop Kharif/Zaid | I9: Zaid Crop
A10: 2018 | B10: =SUMIFS('Data(perSeason,perCrop)'!$A:$A,'Data(perSeason,perCrop)'!$S:$S,Cropping_Intensity!$A10,'Data(perSeason,perCrop)'!$O:$O,Cropping_Intensity!B$7,'Data(perSeason,perCrop)'!$C:$C,Cropping_Intensity!B$4) -> 70.677874 | C10: =SUMIFS('Data(perSeason,perCrop)'!$A:$A,'Data(perSeason,perCrop)'!$S:$S,Cropping_Intensity!$A10,'Data(perSeason,perCrop)'!$O:$O,Cropping_Intensity!C$7,'Data(perSeason,perCrop)'!$C:$C,Cropping_Intensity!C$4) -> 0 | D10: =SUMIFS('Data(perSeason,perCrop)'!$A:$A,'Data(perSeason,perCrop)'!$S:$S,Cropping_Intensity!$A10,'Data(perSeason,perCrop)'!$O:$O,Cropping_Intensity!D$7,'Data(perSeason,perCrop)'!$C:$C,Cropping_Intensity!D$4) -> 0 | E10: =SUMIFS('Data(perSeason,perCrop)'!$A:$A,'Data(perSeason,perCrop)'!$S:$S,Cropping_Intensity!$A10,'Data(perSeason,perCrop)'!$O:$O,Cropping_Intensity!E$7,'Data(perSeason,perCrop)'!$C:$C,Cropping_Intensity!E$4) -> 796.86923 | F10: =SUMIFS('Data(perSeason,perCrop)'!$A:$A,'Data(perSeason,perCrop)'!$S:$S,Cropping_Intensity!$A10,'Data(perSeason,perCrop)'!$O:$O,Cropping_Intensity!F$7,'Data(perSeason,perCrop)'!$C:$C,Cropping_Intensity!F$4) -> 8677.5927 | G10: =SUMIFS('Data(perSeason,perCrop)'!$A:$A,'Data(perSeason,perCrop)'!$S:$S,Cropping_Intensity!$A10,'Data(perSeason,perCrop)'!$O:$O,Cropping_Intensity!G$7,'Data(perSeason,perCrop)'!$C:$C,Cropping_Intensity!G$4) -> 0 | H10: =SUMIFS('Data(perSeason,perCrop)'!$A:$A,'Data(perSeason,perCrop)'!$S:$S,Cropping_Intensity!$A10,'Data(perSeason,perCrop)'!$O:$O,Cropping_Intensity!H$7,'Data(perSeason,perCrop)'!$C:$C,Cropping_Intensity!H$4) -> 2248.9474 | I10: =SUMIFS('Data(perSeason,perCrop)'!$A:$A,'Data(perSeason,perCrop)'!$S:$S,Cropping_Intensity!$A10,'Data(perSeason,perCrop)'!$O:$O,Cropping_Intensity!I$7,'Data(perSeason,perCrop)'!$C:$C,Cropping_Intensity!I$4) -> 0
A11: 2019 | B11: =SUMIFS('Data(perSeason,perCrop)'!$A:$A,'Data(perSeason,perCrop)'!$S:$S,Cropping_Intensity!$A11,'Data(perSeason,perCrop)'!$O:$O,Cropping_Intensity!B$7,'Data(perSeason,perCrop)'!$C:$C,Cropping_Intensity!B$4) -> 118.67038 | C11: =SUMIFS('Data(perSeason,perCrop)'!$A:$A,'Data(perSeason,perCrop)'!$S:$S,Cropping_Intensity!$A11,'Data(perSeason,perCrop)'!$O:$O,Cropping_Intensity!C$7,'Data(perSeason,perCrop)'!$C:$C,Cropping_Intensity!C$4) -> 49.024806 | D11: =SUMIFS('Data(perSeason,perCrop)'!$A:$A,'Data(perSeason,perCrop)'!$S:$S,Cropping_Intensity!$A11,'Data(perSeason,perCrop)'!$O:$O,Cropping_Intensity!D$7,'Data(perSeason,perCrop)'!$C:$C,Cropping_Intensity!D$4) -> 107.79733 | E11: =SUMIFS('Data(perSeason,perCrop)'!$A:$A,'Data(perSeason,perCrop)'!$S:$S,Cropping_Intensity!$A11,'Data(perSeason,perCrop)'!$O:$O,Cropping_Intensity!E$7,'Data(perSeason,perCrop)'!$C:$C,Cropping_Intensity!E$4) -> 3774.4034 | F11: =SUMIFS('Data(perSeason,perCrop)'!$A:$A,'Data(perSeason,perCrop)'!$S:$S,Cropping_Intensity!$A11,'Data(perSeason,perCrop)'!$O:$O,Cropping_Intensity!F$7,'Data(perSeason,perCrop)'!$C:$C,Cropping_Intensity!F$4) -> 4537.6773 | G11: =SUMIFS('Data(perSeason,perCrop)'!$A:$A,'Data(perSeason,perCrop)'!$S:$S,Cropping_Intensity!$A11,'Data(perSeason,perCrop)'!$O:$O,Cropping_Intensity!G$7,'Data(perSeason,perCrop)'!$C:$C,Cropping_Intensity!G$4) -> 120.27067 | H11: =SUMIFS('Data(perSeason,perCrop)'!$A:$A,'Data(perSeason,perCrop)'!$S:$S,Cropping_Intensity!$A11,'Data(perSeason,perCrop)'!$O:$O,Cropping_Intensity!H$7,'Data(perSeason,perCrop)'!$C:$C,Cropping_Intensity!H$4) -> 4888.8774 | I11: =SUMIFS('Data(perSeason,perCrop)'!$A:$A,'Data(perSeason,perCrop)'!$S:$S,Cropping_Intensity!$A11,'Data(perSeason,perCrop)'!$O:$O,Cropping_Intensity!I$7,'Data(perSeason,perCrop)'!$C:$C,Cropping_Intensity!I$4) -> 7.8892189
A12: 2020 | B12: =SUMIFS('Data(perSeason,perCrop)'!$A:$A,'Data(perSeason,perCrop)'!$S:$S,Cropping_Intensity!$A12,'Data(perSeason,perCrop)'!$O:$O,Cropping_Intensity!B$7,'Data(perSeason,perCrop)'!$C:$C,Cropping_Intensity!B$4) -> 59.597834 | C12: =SUMIFS('Data(perSeason,perCrop)'!$A:$A,'Data(perSeason,perCrop)'!$S:$S,Cropping_Intensity!$A12,'Data(perSeason,perCrop)'!$O:$O,Cropping_Intensity!C$7,'Data(perSeason,perCrop)'!$C:$C,Cropping_Intensity!C$4) -> 15.666136 | D12: =SUMIFS('Data(perSeason,perCrop)'!$A:$A,'Data(perSeason,perCrop)'!$S:$S,Cropping_Intensity!$A12,'Data(perSeason,perCrop)'!$O:$O,Cropping_Intensity!D$7,'Data(perSeason,perCrop)'!$C:$C,Cropping_Intensity!D$4) -> 6.7832797 | E12: =SUMIFS('Data(perSeason,perCrop)'!$A:$A,'Data(perSeason,perCrop)'!$S:$S,Cropping_Intensity!$A12,'Data(perSeason,perCrop)'!$O:$O,Cropping_Intensity!E$7,'Data(perSeason,perCrop)'!$C:$C,Cropping_Intensity!E$4) -> 306.93799 | F12: =SUMIFS('Data(perSeason,perCrop)'!$A:$A,'Data(perSeason,perCrop)'!$S:$S,Cropping_Intensity!$A12,'Data(perSeason,perCrop)'!$O:$O,Cropping_Intensity!F$7,'Data(perSeason,perCrop)'!$C:$C,Cropping_Intensity!F$4) -> 7898.0791 | G12: =SUMIFS('Data(perSeason,perCrop)'!$A:$A,'Data(perSeason,perCrop)'!$S:$S,Cropping_Intensity!$A12,'Data(perSeason,perCrop)'!$O:$O,Cropping_Intensity!G$7,'Data(perSeason,perCrop)'!$C:$C,Cropping_Intensity!G$4) -> 13.218432 | H12: =SUMIFS('Data(perSeason,perCrop)'!$A:$A,'Data(perSeason,perCrop)'!$S:$S,Cropping_Intensity!$A12,'Data(perSeason,perCrop)'!$O:$O,Cropping_Intensity!H$7,'Data(perSeason,perCrop)'!$C:$C,Cropping_Intensity!H$4) -> 2257.1429 | I12: =SUMIFS('Data(perSeason,perCrop)'!$A:$A,'Data(perSeason,perCrop)'!$S:$S,Cropping_Intensity!$A12,'Data(perSeason,perCrop)'!$O:$O,Cropping_Intensity!I$7,'Data(perSeason,perCrop)'!$C:$C,Cropping_Intensity!I$4) -> 0
A13: 2021 | B13: =SUMIFS('Data(perSeason,perCrop)'!$A:$A,'Data(perSeason,perCrop)'!$S:$S,Cropping_Intensity!$A13,'Data(perSeason,perCrop)'!$O:$O,Cropping_Intensity!B$7,'Data(perSeason,perCrop)'!$C:$C,Cropping_Intensity!B$4) -> 114.53169 | C13: =SUMIFS('Data(perSeason,perCrop)'!$A:$A,'Data(perSeason,perCrop)'!$S:$S,Cropping_Intensity!$A13,'Data(perSeason,perCrop)'!$O:$O,Cropping_Intensity!C$7,'Data(perSeason,perCrop)'!$C:$C,Cropping_Intensity!C$4) -> 14.3836 | D13: =SUMIFS('Data(perSeason,perCrop)'!$A:$A,'Data(perSeason,perCrop)'!$S:$S,Cropping_Intensity!$A13,'Data(perSeason,perCrop)'!$O:$O,Cropping_Intensity!D$7,'Data(perSeason,perCrop)'!$C:$C,Cropping_Intensity!D$4) -> 11.209214 | E13: =SUMIFS('Data(perSeason,perCrop)'!$A:$A,'Data(perSeason,perCrop)'!$S:$S,Cropping_Intensity!$A13,'Data(perSeason,perCrop)'!$O:$O,Cropping_Intensity!E$7,'Data(perSeason,perCrop)'!$C:$C,Cropping_Intensity!E$4) -> 648.99691 | F13: =SUMIFS('Data(perSeason,perCrop)'!$A:$A,'Data(perSeason,perCrop)'!$S:$S,Cropping_Intensity!$A13,'Data(perSeason,perCrop)'!$O:$O,Cropping_Intensity!F$7,'Data(perSeason,perCrop)'!$C:$C,Cropping_Intensity!F$4) -> 6029.0039 | G13: =SUMIFS('Data(perSeason,perCrop)'!$A:$A,'Data(perSeason,perCrop)'!$S:$S,Cropping_Intensity!$A13,'Data(perSeason,perCrop)'!$O:$O,Cropping_Intensity!G$7,'Data(perSeason,perCrop)'!$C:$C,Cropping_Intensity!G$4) -> 82.084902 | H13: =SUMIFS('Data(perSeason,perCrop)'!$A:$A,'Data(perSeason,perCrop)'!$S:$S,Cropping_Intensity!$A13,'Data(perSeason,perCrop)'!$O:$O,Cropping_Intensity!H$7,'Data(perSeason,perCrop)'!$C:$C,Cropping_Intensity!H$4) -> 2122.9211 | I13: =SUMIFS('Data(perSeason,perCrop)'!$A:$A,'Data(perSeason,perCrop)'!$S:$S,Cropping_Intensity!$A13,'Data(perSeason,perCrop)'!$O:$O,Cropping_Intensity!I$7,'Data(perSeason,perCrop)'!$C:$C,Cropping_Intensity!I$4) -> 0
A14: 2022 | B14: =SUMIFS('Data(perSeason,perCrop)'!$A:$A,'Data(perSeason,perCrop)'!$S:$S,Cropping_Intensity!$A14,'Data(perSeason,perCrop)'!$O:$O,Cropping_Intensity!B$7,'Data(perSeason,perCrop)'!$C:$C,Cropping_Intensity!B$4) -> 11.589767 | C14: =SUMIFS('Data(perSeason,perCrop)'!$A:$A,'Data(perSeason,perCrop)'!$S:$S,Cropping_Intensity!$A14,'Data(perSeason,perCrop)'!$O:$O,Cropping_Intensity!C$7,'Data(perSeason,perCrop)'!$C:$C,Cropping_Intensity!C$4) -> 0 | D14: =SUMIFS('Data(perSeason,perCrop)'!$A:$A,'Data(perSeason,perCrop)'!$S:$S,Cropping_Intensity!$A14,'Data(perSeason,perCrop)'!$O:$O,Cropping_Intensity!D$7,'Data(perSeason,perCrop)'!$C:$C,Cropping_Intensity!D$4) -> 0 | E14: =SUMIFS('Data(perSeason,perCrop)'!$A:$A,'Data(perSeason,perCrop)'!$S:$S,Cropping_Intensity!$A14,'Data(perSeason,perCrop)'!$O:$O,Cropping_Intensity!E$7,'Data(perSeason,perCrop)'!$C:$C,Cropping_Intensity!E$4) -> 708.97698 | F14: =SUMIFS('Data(perSeason,perCrop)'!$A:$A,'Data(perSeason,perCrop)'!$S:$S,Cropping_Intensity!$A14,'Data(perSeason,perCrop)'!$O:$O,Cropping_Intensity!F$7,'Data(perSeason,perCrop)'!$C:$C,Cropping_Intensity!F$4) -> 8199.9696 | G14: =SUMIFS('Data(perSeason,perCrop)'!$A:$A,'Data(perSeason,perCrop)'!$S:$S,Cropping_Intensity!$A14,'Data(perSeason,perCrop)'!$O:$O,Cropping_Intensity!G$7,'Data(perSeason,perCrop)'!$C:$C,Cropping_Intensity!G$4) -> 0 | H14: =SUMIFS('Data(perSeason,perCrop)'!$A:$A,'Data(perSeason,perCrop)'!$S:$S,Cropping_Intensity!$A14,'Data(perSeason,perCrop)'!$O:$O,Cropping_Intensity!H$7,'Data(perSeason,perCrop)'!$C:$C,Cropping_Intensity!H$4) -> 4402.2663 | I14: =SUMIFS('Data(perSeason,perCrop)'!$A:$A,'Data(perSeason,perCrop)'!$S:$S,Cropping_Intensity!$A14,'Data(perSeason,perCrop)'!$O:$O,Cropping_Intensity!I$7,'Data(perSeason,perCrop)'!$C:$C,Cropping_Intensity!I$4) -> 0
A15: 2018-2022 | B15: =AVERAGE(B10:B14) -> 75.013509 | C15: =AVERAGE(C10:C14) -> 15.814908 | D15: =AVERAGE(D10:D14) -> 25.157964 | E15: =AVERAGE(E10:E14) -> 1247.2369 | F15: =AVERAGE(F10:F14) -> 7068.4645 | G15: =AVERAGE(G10:G14) -> 43.114801 | H15: =AVERAGE(H10:H14) -> 3184.031 | I15: =AVERAGE(I10:I14) -> 1.5778438
A17: Cropped Area | B17: Double Crop Kharif/Rabi | C17: Double Crop Rabi/Zaid | D17: Triple Crop | E17: Perennial Crops | F17: Kharif Crop | G17: Rabi Crop | H17: Double Crop Kharif/Zaid | I17: Zaid Crop
A18: 2018 | B18: =B10*B$6/$B$2 -> 0.0081822035 | C18: =C10*C$6/$B$2 -> 0 | D18: =D10*D$6/$B$2 -> 0 | E18: =E10*E$6/$B$2 -> 0.046125795 | F18: =F10*F$6/$B$2 -> 0.50229177 | G18: =G10*G$6/$B$2 -> 0 | H18: =H10*H$6/$B$2 -> 0.26035511 | I18: =I10*I$6/$B$2 -> 0
A19: 2019 | B19: =B11*B$6/$B$2 -> 0.013738178 | C19: =C11*C$6/$B$2 -> 0.0056754811 | D19: =D11*D$6/$B$2 -> 0.018719147 | E19: =E11*E$6/$B$2 -> 0.2184767 | F19: =F11*F$6/$B$2 -> 0.26265786 | G19: =G11*G$6/$B$2 -> 0.0069617197 | H19: =H11*H$6/$B$2 -> 0.56597331 | I19: =I11*I$6/$B$2 -> 0.00045665773
A20: 2020 | B20: =B12*B$6/$B$2 -> 0.0068994946 | C20: =C12*C$6/$B$2 -> 0.00181363 | D20: =D12*D$6/$B$2 -> 0.0011779254 | E20: =E12*E$6/$B$2 -> 0.017766728 | F20: =F12*F$6/$B$2 -> 0.45717059 | G20: =G12*G$6/$B$2 -> 0.00076513268 | H20: =H12*H$6/$B$2 -> 0.26130388 | I20: =I12*I$6/$B$2 -> 0
A21: 2021 | B21: =B13*B$6/$B$2 -> 0.013259052 | C21: =C13*C$6/$B$2 -> 0.001665154 | D21: =D13*D$6/$B$2 -> 0.0019464947 | E21: =E13*E$6/$B$2 -> 0.037566388 | F21: =F13*F$6/$B$2 -> 0.34898147 | G21: =G13*G$6/$B$2 -> 0.0047513835 | H21: =H13*H$6/$B$2 -> 0.24576536 | I21: =I13*I$6/$B$2 -> 0
A22: 2022 | B22: =B14*B$6/$B$2 -> 0.0013417188 | C22: =C14*C$6/$B$2 -> 0 | D22: =D14*D$6/$B$2 -> 0 | E22: =E14*E$6/$B$2 -> 0.04103826 | F22: =F14*F$6/$B$2 -> 0.47464515 | G22: =G14*G$6/$B$2 -> 0 | H22: =H14*H$6/$B$2 -> 0.50963953 | I22: =I14*I$6/$B$2 -> 0
A23: 2018-2022 | B23: =AVERAGE(B18:B22) -> 0.0086841293 | C23: =AVERAGE(C18:C22) -> 0.001830853 | D23: =AVERAGE(D18:D22) -> 0.0043687134 | E23: =AVERAGE(E18:E22) -> 0.072194773 | F23: =AVERAGE(F18:F22) -> 0.40914937 | G23: =AVERAGE(G18:G22) -> 0.0024956472 | H23: =AVERAGE(H18:H22) -> 0.36860744 | I23: =AVERAGE(I18:I22) -> 9.1331546e-05
A25: Based on CCA | B25: Cropping Intensity | C25: Total Cropped Area
A26: 2018 | B26: =SUM(B18:I18) -> 0.81695488 | C26: =B26*B$2 -> 14113.712
A27: 2019 | B27: =SUM(B19:I19) -> 1.092659 | C27: =B27*B$2 -> 18876.778
A28: 2020 | B28: =SUM(B20:I20) -> 0.74689739 | C28: =B28*B$2 -> 12903.399
A29: 2021 | B29: =SUM(B21:I21) -> 0.6539353 | C29: =B29*B$2 -> 11297.386
A30: 2022 | B30: =SUM(B22:I22) -> 1.0266647 | C30: =B30*B$2 -> 17736.659
A31: 2018-2022 | B31: =AVERAGE(B26:B30) -> 0.86742226 | C31: =AVERAGE(C26:C30) -> 14985.587

Sheet Indicators
M23: =IF(COUNTIFS('Data(perSeason,perCrop)'!$S:$S,Indicators!$B87)>0,'[2]Indicators(perCrop)'!AH$38,"")

Sheet Irrigation_Utilization
A2: CCA | B2: 17276 | D2: User Specified
B4: Double Crop Kharif/Rabi | C4: Double Crop Rabi/Zaid | D4: Triple Crop | E4: Perennial Crops | F4: Kharif Crop | G4: Rabi Crop | H4: Double Crop Kharif/Zaid | I4: Zaid Crop
A5: ID | B5: 1 | C5: 2 | D5: 3 | E5: 4 | F5: 5 | G5: 6 | H5: 7 | I5: 8
A6: Cropping Intensity | B6: 2 | C6: 2 | D6: 3 | E6: 1 | F6: 1 | G6: 1 | H6: 2 | I6: 1
A7: Season (Annual) | B7: 0 | C7: 0 | D7: 0 | E7: 0 | F7: 0 | G7: 0 | H7: 0 | I7: 0
A9: Cropped Area | B9: Double Crop Kharif/Rabi | C9: Double Crop Rabi/Zaid | D9: Triple Crop | E9: Perennial Crops | F9: Kharif Crop | G9: Rabi Crop | H9: Double Crop Kharif/Zaid | I9: Zaid Crop | J9: Total
A10: 2018 | B10: =SUMIFS('Data(perSeason,perCrop)'!$A:$A,'Data(perSeason,perCrop)'!$S:$S,Irrigation_Utilization!$A10,'Data(perSeason,perCrop)'!$O:$O,Irrigation_Utilization!B$7,'Data(perSeason,perCrop)'!$C:$C,Irrigation_Utilization!B$4,'Data(perSeason,perCrop)'!$R:$R,"IRRIGATED" ) -> 59.843344 | C10: =SUMIFS('Data(perSeason,perCrop)'!$A:$A,'Data(perSeason,perCrop)'!$S:$S,Irrigation_Utilization!$A10,'Data(perSeason,perCrop)'!$O:$O,Irrigation_Utilization!C$7,'Data(perSeason,perCrop)'!$C:$C,Irrigation_Utilization!C$4,'Data(perSeason,perCrop)'!$R:$R,"IRRIGATED" ) -> 0 | D10: =SUMIFS('Data(perSeason,perCrop)'!$A:$A,'Data(perSeason,perCrop)'!$S:$S,Irrigation_Utilization!$A10,'Data(perSeason,perCrop)'!$O:$O,Irrigation_Utilization!D$7,'Data(perSeason,perCrop)'!$C:$C,Irrigation_Utilization!D$4,'Data(perSeason,perCrop)'!$R:$R,"IRRIGATED" ) -> 0 | E10: =SUMIFS('Data(perSeason,perCrop)'!$A:$A,'Data(perSeason,perCrop)'!$S:$S,Irrigation_Utilization!$A10,'Data(perSeason,perCrop)'!$O:$O,Irrigation_Utilization!E$7,'Data(perSeason,perCrop)'!$C:$C,Irrigation_Utilization!E$4,'Data(perSeason,perCrop)'!$R:$R,"IRRIGATED" ) -> 674.8299 | F10: =SUMIFS('Data(perSeason,perCrop)'!$A:$A,'Data(perSeason,perCrop)'!$S:$S,Irrigation_Utilization!$A10,'Data(perSeason,perCrop)'!$O:$O,Irrigation_Utilization!F$7,'Data(perSeason,perCrop)'!$C:$C,Irrigation_Utilization!F$4,'Data(perSeason,perCrop)'!$R:$R,"IRRIGATED" ) -> 6429.0186 | G10: =SUMIFS('Data(perSeason,perCrop)'!$A:$A,'Data(perSeason,perCrop)'!$S:$S,Irrigation_Utilization!$A10,'Data(perSeason,perCrop)'!$O:$O,Irrigation_Utilization!G$7,'Data(perSeason,perCrop)'!$C:$C,Irrigation_Utilization!G$4,'Data(perSeason,perCrop)'!$R:$R,"IRRIGATED" ) -> 0 | H10: =SUMIFS('Data(perSeason,perCrop)'!$A:$A,'Data(perSeason,perCrop)'!$S:$S,Irrigation_Utilization!$A10,'Data(perSeason,perCrop)'!$O:$O,Irrigation_Utilization!H$7,'Data(perSeason,perCrop)'!$C:$C,Irrigation_Utilization!H$4,'Data(perSeason,perCrop)'!$R:$R,"IRRIGATED" ) -> 2204.0052 | I10: =SUMIFS('Data(perSeason,perCrop)'!$A:$A,'Data(perSeason,perCrop)'!$S:$S,Irrigation_Utilization!$A10,'Data(perSeason,perCrop)'!$O:$O,Irrigation_Utilization!I$7,'Data(perSeason,perCrop)'!$C:$C,Irrigation_Utilization!I$4,'Data(perSeason,perCrop)'!$R:$R,"IRRIGATED" ) -> 0 | J10: =SUM(B10:I10) -> 9367.697
A11: 2019 | B11: =SUMIFS('Data(perSeason,perCrop)'!$A:$A,'Data(perSeason,perCrop)'!$S:$S,Irrigation_Utilization!$A11,'Data(perSeason,perCrop)'!$O:$O,Irrigation_Utilization!B$7,'Data(perSeason,perCrop)'!$C:$C,Irrigation_Utilization!B$4,'Data(perSeason,perCrop)'!$R:$R,"IRRIGATED" ) -> 75.894637 | C11: =SUMIFS('Data(perSeason,perCrop)'!$A:$A,'Data(perSeason,perCrop)'!$S:$S,Irrigation_Utilization!$A11,'Data(perSeason,perCrop)'!$O:$O,Irrigation_Utilization!C$7,'Data(perSeason,perCrop)'!$C:$C,Irrigation_Utilization!C$4,'Data(perSeason,perCrop)'!$R:$R,"IRRIGATED" ) -> 49.024806 | D11: =SUMIFS('Data(perSeason,perCrop)'!$A:$A,'Data(perSeason,perCrop)'!$S:$S,Irrigation_Utilization!$A11,'Data(perSeason,perCrop)'!$O:$O,Irrigation_Utilization!D$7,'Data(perSeason,perCrop)'!$C:$C,Irrigation_Utilization!D$4,'Data(perSeason,perCrop)'!$R:$R,"IRRIGATED" ) -> 107.79733 | E11: =SUMIFS('Data(perSeason,perCrop)'!$A:$A,'Data(perSeason,perCrop)'!$S:$S,Irrigation_Utilization!$A11,'Data(perSeason,perCrop)'!$O:$O,Irrigation_Utilization!E$7,'Data(perSeason,perCrop)'!$C:$C,Irrigation_Utilization!E$4,'Data(perSeason,perCrop)'!$R:$R,"IRRIGATED" ) -> 3035.494 | F11: =SUMIFS('Data(perSeason,perCrop)'!$A:$A,'Data(perSeason,perCrop)'!$S:$S,Irrigation_Utilization!$A11,'Data(perSeason,perCrop)'!$O:$O,Irrigation_Utilization!F$7,'Data(perSeason,perCrop)'!$C:$C,Irrigation_Utilization!F$4,'Data(perSeason,perCrop)'!$R:$R,"IRRIGATED" ) -> 2517.5209 | G11: =SUMIFS('Data(perSeason,perCrop)'!$A:$A,'Data(perSeason,perCrop)'!$S:$S,Irrigation_Utilization!$A11,'Data(perSeason,perCrop)'!$O:$O,Irrigation_Utilization!G$7,'Data(perSeason,perCrop)'!$C:$C,Irrigation_Utilization!G$4,'Data(perSeason,perCrop)'!$R:$R,"IRRIGATED" ) -> 80.534693 | H11: =SUMIFS('Data(perSeason,perCrop)'!$A:$A,'Data(perSeason,perCrop)'!$S:$S,Irrigation_Utilization!$A11,'Data(perSeason,perCrop)'!$O:$O,Irrigation_Utilization!H$7,'Data(perSeason,perCrop)'!$C:$C,Irrigation_Utilization!H$4,'Data(perSeason,perCrop)'!$R:$R,"IRRIGATED" ) -> 4609.0601 | I11: =SUMIFS('Data(perSeason,perCrop)'!$A:$A,'Data(perSeason,perCrop)'!$S:$S,Irrigation_Utilization!$A11,'Data(perSeason,perCrop)'!$O:$O,Irrigation_Utilization!I$7,'Data(perSeason,perCrop)'!$C:$C,Irrigation_Utilization!I$4,'Data(perSeason,perCrop)'!$R:$R,"IRRIGATED" ) -> 7.8892189 | J11: =SUM(B11:I11) -> 10483.216
A12: 2020 | B12: =SUMIFS('Data(perSeason,perCrop)'!$A:$A,'Data(perSeason,perCrop)'!$S:$S,Irrigation_Utilization!$A12,'Data(perSeason,perCrop)'!$O:$O,Irrigation_Utilization!B$7,'Data(perSeason,perCrop)'!$C:$C,Irrigation_Utilization!B$4,'Data(perSeason,perCrop)'!$R:$R,"IRRIGATED" ) -> 25.360404 | C12: =SUMIFS('Data(perSeason,perCrop)'!$A:$A,'Data(perSeason,perCrop)'!$S:$S,Irrigation_Utilization!$A12,'Data(perSeason,perCrop)'!$O:$O,Irrigation_Utilization!C$7,'Data(perSeason,perCrop)'!$C:$C,Irrigation_Utilization!C$4,'Data(perSeason,perCrop)'!$R:$R,"IRRIGATED" ) -> 15.666136 | D12: =SUMIFS('Data(perSeason,perCrop)'!$A:$A,'Data(perSeason,perCrop)'!$S:$S,Irrigation_Utilization!$A12,'Data(perSeason,perCrop)'!$O:$O,Irrigation_Utilization!D$7,'Data(perSeason,perCrop)'!$C:$C,Irrigation_Utilization!D$4,'Data(perSeason,perCrop)'!$R:$R,"IRRIGATED" ) -> 6.7832797 | E12: =SUMIFS('Data(perSeason,perCrop)'!$A:$A,'Data(perSeason,perCrop)'!$S:$S,Irrigation_Utilization!$A12,'Data(perSeason,perCrop)'!$O:$O,Irrigation_Utilization!E$7,'Data(perSeason,perCrop)'!$C:$C,Irrigation_Utilization!E$4,'Data(perSeason,perCrop)'!$R:$R,"IRRIGATED" ) -> 251.17421 | F12: =SUMIFS('Data(perSeason,perCrop)'!$A:$A,'Data(perSeason,perCrop)'!$S:$S,Irrigation_Utilization!$A12,'Data(perSeason,perCrop)'!$O:$O,Irrigation_Utilization!F$7,'Data(perSeason,perCrop)'!$C:$C,Irrigation_Utilization!F$4,'Data(perSeason,perCrop)'!$R:$R,"IRRIGATED" ) -> 3835.7191 | G12: =SUMIFS('Data(perSeason,perCrop)'!$A:$A,'Data(perSeason,perCrop)'!$S:$S,Irrigation_Utilization!$A12,'Data(perSeason,perCrop)'!$O:$O,Irrigation_Utilization!G$7,'Data(perSeason,perCrop)'!$C:$C,Irrigation_Utilization!G$4,'Data(perSeason,perCrop)'!$R:$R,"IRRIGATED" ) -> 0 | H12: =SUMIFS('Data(perSeason,perCrop)'!$A:$A,'Data(perSeason,perCrop)'!$S:$S,Irrigation_Utilization!$A12,'Data(perSeason,perCrop)'!$O:$O,Irrigation_Utilization!H$7,'Data(perSeason,perCrop)'!$C:$C,Irrigation_Utilization!H$4,'Data(perSeason,perCrop)'!$R:$R,"IRRIGATED" ) -> 2154.3017 | I12: =SUMIFS('Data(perSeason,perCrop)'!$A:$A,'Data(perSeason,perCrop)'!$S:$S,Irrigation_Utilization!$A12,'Data(perSeason,perCrop)'!$O:$O,Irrigation_Utilization!I$7,'Data(perSeason,perCrop)'!$C:$C,Irrigation_Utilization!I$4,'Data(perSeason,perCrop)'!$R:$R,"IRRIGATED" ) -> 0 | J12: =SUM(B12:I12) -> 6289.0048
A13: 2021 | B13: =SUMIFS('Data(perSeason,perCrop)'!$A:$A,'Data(perSeason,perCrop)'!$S:$S,Irrigation_Utilization!$A13,'Data(perSeason,perCrop)'!$O:$O,Irrigation_Utilization!B$7,'Data(perSeason,perCrop)'!$C:$C,Irrigation_Utilization!B$4,'Data(perSeason,perCrop)'!$R:$R,"IRRIGATED" ) -> 67.455545 | C13: =SUMIFS('Data(perSeason,perCrop)'!$A:$A,'Data(perSeason,perCrop)'!$S:$S,Irrigation_Utilization!$A13,'Data(perSeason,perCrop)'!$O:$O,Irrigation_Utilization!C$7,'Data(perSeason,perCrop)'!$C:$C,Irrigation_Utilization!C$4,'Data(perSeason,perCrop)'!$R:$R,"IRRIGATED" ) -> 14.3836 | D13: =SUMIFS('Data(perSeason,perCrop)'!$A:$A,'Data(perSeason,perCrop)'!$S:$S,Irrigation_Utilization!$A13,'Data(perSeason,perCrop)'!$O:$O,Irrigation_Utilization!D$7,'Data(perSeason,perCrop)'!$C:$C,Irrigation_Utilization!D$4,'Data(perSeason,perCrop)'!$R:$R,"IRRIGATED" ) -> 11.209214 | E13: =SUMIFS('Data(perSeason,perCrop)'!$A:$A,'Data(perSeason,perCrop)'!$S:$S,Irrigation_Utilization!$A13,'Data(perSeason,perCrop)'!$O:$O,Irrigation_Utilization!E$7,'Data(perSeason,perCrop)'!$C:$C,Irrigation_Utilization!E$4,'Data(perSeason,perCrop)'!$R:$R,"IRRIGATED" ) -> 561.88327 | F13: =SUMIFS('Data(perSeason,perCrop)'!$A:$A,'Data(perSeason,perCrop)'!$S:$S,Irrigation_Utilization!$A13,'Data(perSeason,perCrop)'!$O:$O,Irrigation_Utilization!F$7,'Data(perSeason,perCrop)'!$C:$C,Irrigation_Utilization!F$4,'Data(perSeason,perCrop)'!$R:$R,"IRRIGATED" ) -> 4053.7929 | G13: =SUMIFS('Data(perSeason,perCrop)'!$A:$A,'Data(perSeason,perCrop)'!$S:$S,Irrigation_Utilization!$A13,'Data(perSeason,perCrop)'!$O:$O,Irrigation_Utilization!G$7,'Data(perSeason,perCrop)'!$C:$C,Irrigation_Utilization!G$4,'Data(perSeason,perCrop)'!$R:$R,"IRRIGATED" ) -> 33.569078 | H13: =SUMIFS('Data(perSeason,perCrop)'!$A:$A,'Data(perSeason,perCrop)'!$S:$S,Irrigation_Utilization!$A13,'Data(perSeason,perCrop)'!$O:$O,Irrigation_Utilization!H$7,'Data(perSeason,perCrop)'!$C:$C,Irrigation_Utilization!H$4,'Data(perSeason,perCrop)'!$R:$R,"IRRIGATED" ) -> 2093.7228 | I13: =SUMIFS('Data(perSeason,perCrop)'!$A:$A,'Data(perSeason,perCrop)'!$S:$S,Irrigation_Utilization!$A13,'Data(perSeason,perCrop)'!$O:$O,Irrigation_Utilization!I$7,'Data(perSeason,perCrop)'!$C:$C,Irrigation_Utilization!I$4,'Data(perSeason,perCrop)'!$R:$R,"IRRIGATED" ) -> 0 | J13: =SUM(B13:I13) -> 6836.0164
A14: 2022 | B14: =SUMIFS('Data(perSeason,perCrop)'!$A:$A,'Data(perSeason,perCrop)'!$S:$S,Irrigation_Utilization!$A14,'Data(perSeason,perCrop)'!$O:$O,Irrigation_Utilization!B$7,'Data(perSeason,perCrop)'!$C:$C,Irrigation_Utilization!B$4,'Data(perSeason,perCrop)'!$R:$R,"IRRIGATED" ) -> 0 | C14: =SUMIFS('Data(perSeason,perCrop)'!$A:$A,'Data(perSeason,perCrop)'!$S:$S,Irrigation_Utilization!$A14,'Data(perSeason,perCrop)'!$O:$O,Irrigation_Utilization!C$7,'Data(perSeason,perCrop)'!$C:$C,Irrigation_Utilization!C$4,'Data(perSeason,perCrop)'!$R:$R,"IRRIGATED" ) -> 0 | D14: =SUMIFS('Data(perSeason,perCrop)'!$A:$A,'Data(perSeason,perCrop)'!$S:$S,Irrigation_Utilization!$A14,'Data(perSeason,perCrop)'!$O:$O,Irrigation_Utilization!D$7,'Data(perSeason,perCrop)'!$C:$C,Irrigation_Utilization!D$4,'Data(perSeason,perCrop)'!$R:$R,"IRRIGATED" ) -> 0 | E14: =SUMIFS('Data(perSeason,perCrop)'!$A:$A,'Data(perSeason,perCrop)'!$S:$S,Irrigation_Utilization!$A14,'Data(perSeason,perCrop)'!$O:$O,Irrigation_Utilization!E$7,'Data(perSeason,perCrop)'!$C:$C,Irrigation_Utilization!E$4,'Data(perSeason,perCrop)'!$R:$R,"IRRIGATED" ) -> 597.41535 | F14: =SUMIFS('Data(perSeason,perCrop)'!$A:$A,'Data(perSeason,perCrop)'!$S:$S,Irrigation_Utilization!$A14,'Data(perSeason,perCrop)'!$O:$O,Irrigation_Utilization!F$7,'Data(perSeason,perCrop)'!$C:$C,Irrigation_Utilization!F$4,'Data(perSeason,perCrop)'!$R:$R,"IRRIGATED" ) -> 4785.7117 | G14: =SUMIFS('Data(perSeason,perCrop)'!$A:$A,'Data(perSeason,perCrop)'!$S:$S,Irrigation_Utilization!$A14,'Data(perSeason,perCrop)'!$O:$O,Irrigation_Utilization!G$7,'Data(perSeason,perCrop)'!$C:$C,Irrigation_Utilization!G$4,'Data(perSeason,perCrop)'!$R:$R,"IRRIGATED" ) -> 0 | H14: =SUMIFS('Data(perSeason,perCrop)'!$A:$A,'Data(perSeason,perCrop)'!$S:$S,Irrigation_Utilization!$A14,'Data(perSeason,perCrop)'!$O:$O,Irrigation_Utilization!H$7,'Data(perSeason,perCrop)'!$C:$C,Irrigation_Utilization!H$4,'Data(perSeason,perCrop)'!$R:$R,"IRRIGATED" ) -> 4069.1684 | I14: =SUMIFS('Data(perSeason,perCrop)'!$A:$A,'Data(perSeason,perCrop)'!$S:$S,Irrigation_Utilization!$A14,'Data(perSeason,perCrop)'!$O:$O,Irrigation_Utilization!I$7,'Data(perSeason,perCrop)'!$C:$C,Irrigation_Utilization!I$4,'Data(perSeason,perCrop)'!$R:$R,"IRRIGATED" ) -> 0 | J14: =SUM(B14:I14) -> 9452.2954
A15: 2018-2022 | B15: =AVERAGE(B10:B14) -> 45.710786 | C15: =AVERAGE(C10:C14) -> 15.814908 | D15: =AVERAGE(D10:D14) -> 25.157964 | E15: =AVERAGE(E10:E14) -> 1024.1593 | F15: =AVERAGE(F10:F14) -> 4324.3526 | G15: =AVERAGE(G10:G14) -> 22.820754 | H15: =AVERAGE(H10:H14) -> 3026.0516 | I15: =AVERAGE(I10:I14) -> 1.5778438 | J15: =SUM(B15:I15) -> 8485.6459
A17: Cropped Area | B17: Double Crop Kharif/Rabi | C17: Double Crop Rabi/Zaid | D17: Triple Crop | E17: Perennial Crops | F17: Kharif Crop | G17: Rabi Crop | H17: Double Crop Kharif/Zaid | I17: Zaid Crop
A18: 2018 | B18: =B10/$B$2 -> 0.0034639583 | C18: =C10/$B$2 -> 0 | D18: =D10/$B$2 -> 0 | E18: =E10/$B$2 -> 0.039061698 | F18: =F10/$B$2 -> 0.37213583 | G18: =G10/$B$2 -> 0 | H18: =H10/$B$2 -> 0.12757613 | I18: =I10/$B$2 -> 0
A19: 2019 | B19: =B11/$B$2 -> 0.0043930677 | C19: =C11/$B$2 -> 0.0028377405 | D19: =D11/$B$2 -> 0.0062397156 | E19: =E11/$B$2 -> 0.17570583 | F19: =F11/$B$2 -> 0.1457236 | G19: =G11/$B$2 -> 0.0046616516 | H19: =H11/$B$2 -> 0.26678977 | I19: =I11/$B$2 -> 0.00045665773
A20: 2020 | B20: =B12/$B$2 -> 0.0014679558 | C20: =C12/$B$2 -> 0.00090681498 | D20: =D12/$B$2 -> 0.0003926418 | E20: =E12/$B$2 -> 0.01453891 | F20: =F12/$B$2 -> 0.22202588 | G20: =G12/$B$2 -> 0 | H20: =H12/$B$2 -> 0.1246991 | I20: =I12/$B$2 -> 0
A21: 2021 | B21: =B13/$B$2 -> 0.0039045812 | C21: =C13/$B$2 -> 0.00083257698 | D21: =D13/$B$2 -> 0.00064883157 | E21: =E13/$B$2 -> 0.032523921 | F21: =F13/$B$2 -> 0.23464882 | G21: =G13/$B$2 -> 0.0019431047 | H21: =H13/$B$2 -> 0.12119257 | I21: =I13/$B$2 -> 0
A22: 2022 | B22: =B14/$B$2 -> 0 | C22: =C14/$B$2 -> 0 | D22: =D14/$B$2 -> 0 | E22: =E14/$B$2 -> 0.034580652 | F22: =F14/$B$2 -> 0.27701503 | G22: =G14/$B$2 -> 0 | H22: =H14/$B$2 -> 0.2355388 | I22: =I14/$B$2 -> 0
A23: 2018-2022 | B23: =AVERAGE(B18:B22) -> 0.0026459126 | C23: =AVERAGE(C18:C22) -> 0.0009154265 | D23: =AVERAGE(D18:D22) -> 0.0014562378 | E23: =AVERAGE(E18:E22) -> 0.059282203 | F23: =AVERAGE(F18:F22) -> 0.25030983 | G23: =AVERAGE(G18:G22) -> 0.0013209513 | H23: =AVERAGE(H18:H22) -> 0.17515927 | I23: =AVERAGE(I18:I22) -> 9.1331546e-05
A25: Cropped Area | B25: Double Crop Kharif/Rabi | C25: Double Crop Rabi/Zaid | D25: Triple Crop | E25: Perennial Crops | F25: Kharif Crop | G25: Rabi Crop | H25: Double Crop Kharif/Zaid | I25: Zaid Crop | J25: Total
A26: 2018 | B26: =(B10*B$6)/$B$2 -> 0.0069279166 | C26: =(C10*C$6)/$B$2 -> 0 | D26: =(D10*D$6)/$B$2 -> 0 | E26: =(E10*E$6)/$B$2 -> 0.039061698 | F26: =(F10*F$6)/$B$2 -> 0.37213583 | G26: =(G10*G$6)/$B$2 -> 0 | H26: =(H10*H$6)/$B$2 -> 0.25515225 | I26: =(I10*I$6)/$B$2 -> 0 | J26: =SUM(B26:I26) -> 0.6732777
A27: 2019 | B27: =(B11*B$6)/$B$2 -> 0.0087861354 | C27: =(C11*C$6)/$B$2 -> 0.0056754811 | D27: =(D11*D$6)/$B$2 -> 0.018719147 | E27: =(E11*E$6)/$B$2 -> 0.17570583 | F27: =(F11*F$6)/$B$2 -> 0.1457236 | G27: =(G11*G$6)/$B$2 -> 0.0046616516 | H27: =(H11*H$6)/$B$2 -> 0.53357954 | I27: =(I11*I$6)/$B$2 -> 0.00045665773 | J27: =SUM(B27:I27) -> 0.89330805
A28: 2020 | B28: =(B12*B$6)/$B$2 -> 0.0029359116 | C28: =(C12*C$6)/$B$2 -> 0.00181363 | D28: =(D12*D$6)/$B$2 -> 0.0011779254 | E28: =(E12*E$6)/$B$2 -> 0.01453891 | F28: =(F12*F$6)/$B$2 -> 0.22202588 | G28: =(G12*G$6)/$B$2 -> 0 | H28: =(H12*H$6)/$B$2 -> 0.2493982 | I28: =(I12*I$6)/$B$2 -> 0 | J28: =SUM(B28:I28) -> 0.49189046
A29: 2021 | B29: =(B13*B$6)/$B$2 -> 0.0078091624 | C29: =(C13*C$6)/$B$2 -> 0.001665154 | D29: =(D13*D$6)/$B$2 -> 0.0019464947 | E29: =(E13*E$6)/$B$2 -> 0.032523921 | F29: =(F13*F$6)/$B$2 -> 0.23464882 | G29: =(G13*G$6)/$B$2 -> 0.0019431047 | H29: =(H13*H$6)/$B$2 -> 0.24238513 | I29: =(I13*I$6)/$B$2 -> 0 | J29: =SUM(B29:I29) -> 0.52292179
A30: 2022 | B30: =(B14*B$6)/$B$2 -> 0 | C30: =(C14*C$6)/$B$2 -> 0 | D30: =(D14*D$6)/$B$2 -> 0 | E30: =(E14*E$6)/$B$2 -> 0.034580652 | F30: =(F14*F$6)/$B$2 -> 0.27701503 | G30: =(G14*G$6)/$B$2 -> 0 | H30: =(H14*H$6)/$B$2 -> 0.47107761 | I30: =(I14*I$6)/$B$2 -> 0 | J30: =SUM(B30:I30) -> 0.78267329
A31: 2018-2022 | B31: =AVERAGE(B26:B30) -> 0.0052918252 | C31: =AVERAGE(C26:C30) -> 0.001830853 | D31: =AVERAGE(D26:D30) -> 0.0043687134 | E31: =AVERAGE(E26:E30) -> 0.059282203 | F31: =AVERAGE(F26:F30) -> 0.25030983 | G31: =AVERAGE(G26:G30) -> 0.0013209513 | H31: =AVERAGE(H26:H30) -> 0.35031855 | I31: =AVERAGE(I26:I30) -> 9.1331546e-05 | J31: =SUM(B31:I31) -> 0.67281426
A33: Based on CCA | B33: Irrigated Area Fraction | C33: Total Irrigated Area
A34: 2018 | B34: =SUM(B18:I18) -> 0.54223761 | C34: =B34*B$2 -> 9367.697
A35: 2019 | B35: =SUM(B19:I19) -> 0.60680804 | C35: =B35*B$2 -> 10483.216
A36: 2020 | B36: =SUM(B20:I20) -> 0.3640313 | C36: =B36*B$2 -> 6289.0048
A37: 2021 | B37: =SUM(B21:I21) -> 0.3956944 | C37: =B37*B$2 -> 6836.0164
A38: 2022 | B38: =SUM(B22:I22) -> 0.54713449 | C38: =B38*B$2 -> 9452.2954
A39: 2018-2022 | B39: =AVERAGE(B34:B38) -> 0.49118117 | C39: =AVERAGE(C34:C38) -> 8485.6459

Sheet Adequacy
A1: Irrigated Area
A2: Season (KHARIF) | B2: Cotton | C2: Paddy | D2: Maize | E2: Wheat | F2: Redgram | G2: Chickpea | H2: Mustard | I2: Jowar | J2: Chili | K2: Orchard | L2: Groundnut | M2: Potato | N2: Sugarcane | O2: Other Irrigated (High Water Intensive) | P2: Other Irrigated (Less Water Intensive) | Q2: Other Rainfed | R2: Class1 | S2: Class2 | T2: Class3 | U2: Class4 | V2: Class5 | W2: Class6 | X2: Class7 | Y2: Class8 | Z2: Class9 | AA2: Class10 | AB2: Class11 | AC2: Class12 | AD2: Class13 | AE2: Class14 | AF2: Class15
A3: Crop ID | B3: 1 | C3: 2 | D3: 3 | E3: 4 | F3: 5 | G3: 6 | H3: 7 | I3: 8 | J3: 9 | K3: 10 | L3: 11 | M3: 12 | N3: 13 | O3: 14 | P3: 15 | Q3: 16 | R3: 17 | S3: 18 | T3: 19 | U3: 20 | V3: 21 | W3: 22 | X3: 23 | Y3: 24 | Z3: 25 | AA3: 40 | AB3: 41 | AC3: 42 | AD3: 43 | AE3: 44 | AF3: 45
A4: 2018 | B4: =SUMIFS('Data(perSeason,perCrop)'!$A:$A,'Data(perSeason,perCrop)'!$S:$S,Adequacy!$A4,'Data(perSeason,perCrop)'!$O:$O,1,'Data(perSeason,perCrop)'!$C:$C,Adequacy!B$2,'Data(perSeason,perCrop)'!$R:$R,"IRRIGATED") -> 0 | C4: =SUMIFS('Data(perSeason,perCrop)'!$A:$A,'Data(perSeason,perCrop)'!$S:$S,Adequacy!$A4,'Data(perSeason,perCrop)'!$O:$O,1,'Data(perSeason,perCrop)'!$C:$C,Adequacy!C$2,'Data(perSeason,perCrop)'!$R:$R,"IRRIGATED") -> 5050.8789 | D4: =SUMIFS('Data(perSeason,perCrop)'!$A:$A,'Data(perSeason,perCrop)'!$S:$S,Adequacy!$A4,'Data(perSeason,perCrop)'!$O:$O,1,'Data(perSeason,perCrop)'!$C:$C,Adequacy!D$2,'Data(perSeason,perCrop)'!$R:$R,"IRRIGATED") -> 0 | E4: =SUMIFS('Data(perSeason,perCrop)'!$A:$A,'Data(perSeason,perCrop)'!$S:$S,Adequacy!$A4,'Data(perSeason,perCrop)'!$O:$O,1,'Data(perSeason,perCrop)'!$C:$C,Adequacy!E$2,'Data(perSeason,perCrop)'!$R:$R,"IRRIGATED") -> 0 | F4: =SUMIFS('Data(perSeason,perCrop)'!$A:$A,'Data(perSeason,perCrop)'!$S:$S,Adequacy!$A4,'Data(perSeason,perCrop)'!$O:$O,1,'Data(perSeason,perCrop)'!$C:$C,Adequacy!F$2,'Data(perSeason,perCrop)'!$R:$R,"IRRIGATED") -> 0 | G4: =SUMIFS('Data(perSeason,perCrop)'!$A:$A,'Data(perSeason,perCrop)'!$S:$S,Adequacy!$A4,'Data(perSeason,perCrop)'!$O:$O,1,'Data(perSeason,perCrop)'!$C:$C,Adequacy!G$2,'Data(perSeason,perCrop)'!$R:$R,"IRRIGATED") -> 0 | H4: =SUMIFS('Data(perSeason,perCrop)'!$A:$A,'Data(perSeason,perCrop)'!$S:$S,Adequacy!$A4,'Data(perSeason,perCrop)'!$O:$O,1,'Data(perSeason,perCrop)'!$C:$C,Adequacy!H$2,'Data(perSeason,perCrop)'!$R:$R,"IRRIGATED") -> 0 | I4: =SUMIFS('Data(perSeason,perCrop)'!$A:$A,'Data(perSeason,perCrop)'!$S:$S,Adequacy!$A4,'Data(perSeason,perCrop)'!$O:$O,1,'Data(perSeason,perCrop)'!$C:$C,Adequacy!I$2,'Data(perSeason,perCrop)'!$R:$R,"IRRIGATED") -> 0 | ... AF4: =SUMIFS('Data(perSeason,perCrop)'!$A:$A,'Data(perSeason,perCrop)'!$S:$S,Adequacy!$A4,'Data(perSeason,perCrop)'!$O:$O,1,'Data(perSeason,perCrop)'!$C:$C,Adequacy!AF$2,'Data(perSeason,perCrop)'!$R:$R,"IRRIGATED") -> 0
